========== FA3 OPTIMIZED BENCHMARK ==========
Target: <15min | Est. SU: 238.934 | Balance: 41100.447
N/A
Job ID: 97117.pbs111 | GPUs: 16 | Master: a2ap-dgx007.asp2p.nscc.sg:5000
Config: TP16+DP2 | Attention: FlashAttention-3 | NCCL: Optimized
=============================================
[02:26:52] Launching FA3-optimized benchmark...
[1,0]<stdout>:WARNING:sglang.srt.server_args:DP attention is enabled. The chunked prefill size is adjusted to 4096 to avoid MoE kernel issues. 
[1,0]<stdout>:WARNING:sglang.srt.server_args:Overlap scheduler is disabled because of using eagle speculative decoding.
[1,0]<stdout>:WARNING:sglang.srt.server_args:Mixed chunked prefill is disabled because of using eagle speculative decoding.
[1,1]<stdout>:WARNING:sglang.srt.server_args:DP attention is enabled. The chunked prefill size is adjusted to 4096 to avoid MoE kernel issues. 
[1,1]<stdout>:WARNING:sglang.srt.server_args:Overlap scheduler is disabled because of using eagle speculative decoding.
[1,1]<stdout>:WARNING:sglang.srt.server_args:Mixed chunked prefill is disabled because of using eagle speculative decoding.
[1,0]<stdout>:WARNING:sglang.srt.server_args:DP attention is enabled. The chunked prefill size is adjusted to 2048 to avoid MoE kernel issues. 
[1,0]<stdout>:WARNING:sglang.srt.server_args:Overlap scheduler is disabled because of using eagle speculative decoding.
[1,0]<stdout>:WARNING:sglang.srt.server_args:DeepSeek MTP does not require setting speculative_draft_model_path.
[1,0]<stdout>:[2025-10-12 02:27:13] Using default HuggingFace chat template with detected content format: string
[1,1]<stdout>:WARNING:sglang.srt.server_args:DP attention is enabled. The chunked prefill size is adjusted to 2048 to avoid MoE kernel issues. 
[1,1]<stdout>:WARNING:sglang.srt.server_args:Overlap scheduler is disabled because of using eagle speculative decoding.
[1,1]<stdout>:WARNING:sglang.srt.server_args:DeepSeek MTP does not require setting speculative_draft_model_path.
[1,1]<stdout>:[2025-10-12 02:27:56 DP1 TP12] Scheduler hit an exception: Traceback (most recent call last):
[1,1]<stdout>:  File "/home/users/industry/ai-hpc/apacsc34/scratch/tanathep/py312/lib/python3.12/site-packages/sglang/srt/managers/scheduler.py", line 2555, in run_scheduler_process
[1,1]<stdout>:    scheduler = Scheduler(
[1,1]<stdout>:                ^^^^^^^^^^
[1,1]<stdout>:  File "/home/users/industry/ai-hpc/apacsc34/scratch/tanathep/py312/lib/python3.12/site-packages/sglang/srt/managers/scheduler.py", line 315, in __init__
[1,1]<stdout>:    self.tp_worker = TpWorkerClass(
[1,1]<stdout>:                     ^^^^^^^^^^^^^^
[1,1]<stdout>:  File "/home/users/industry/ai-hpc/apacsc34/scratch/tanathep/py312/lib/python3.12/site-packages/sglang/srt/managers/tp_worker.py", line 84, in __init__
[1,1]<stdout>:    self.model_runner = ModelRunner(
[1,1]<stdout>:                        ^^^^^^^^^^^^
[1,1]<stdout>:  File "/home/users/industry/ai-hpc/apacsc34/scratch/tanathep/py312/lib/python3.12/site-packages/sglang/srt/model_executor/model_runner.py", line 213, in __init__
[1,1]<stdout>:    self.model_specific_adjustment()
[1,1]<stdout>:  File "/home/users/industry/ai-hpc/apacsc34/scratch/tanathep/py312/lib/python3.12/site-packages/sglang/srt/model_executor/model_runner.py", line 499, in model_specific_adjustment
[1,1]<stdout>:    self.init_double_sparsity_channel_config(server_args.ds_heavy_channel_type)
[1,1]<stdout>:  File "/home/users/industry/ai-hpc/apacsc34/scratch/tanathep/py312/lib/python3.12/site-packages/sglang/srt/model_executor/model_runner.py", line 1581, in init_double_sparsity_channel_config
[1,1]<stdout>:    with open(self.server_args.ds_channel_config_path, "r") as f:
[1,1]<stdout>:         ^^^^^^^^^^^^^^^^^^^^^^^^^^^^^^^^^^^^^^^^^^^^^^^^^^
[1,1]<stdout>:TypeError: expected str, bytes or os.PathLike object, not NoneType
[1,1]<stdout>:
[1,0]<stdout>:[2025-10-12 02:27:57 DP0 TP2] Scheduler hit an exception: Traceback (most recent call last):
[1,0]<stdout>:  File "/home/users/industry/ai-hpc/apacsc34/scratch/tanathep/py312/lib/python3.12/site-packages/sglang/srt/managers/scheduler.py", line 2555, in run_scheduler_process
[1,0]<stdout>:    scheduler = Scheduler(
[1,0]<stdout>:                ^^^^^^^^^^
[1,0]<stdout>:  File "/home/users/industry/ai-hpc/apacsc34/scratch/tanathep/py312/lib/python3.12/site-packages/sglang/srt/managers/scheduler.py", line 315, in __init__
[1,0]<stdout>:    self.tp_worker = TpWorkerClass(
[1,0]<stdout>:                     ^^^^^^^^^^^^^^
[1,0]<stdout>:  File "/home/users/industry/ai-hpc/apacsc34/scratch/tanathep/py312/lib/python3.12/site-packages/sglang/srt/managers/tp_worker.py", line 84, in __init__
[1,0]<stdout>:    self.model_runner = ModelRunner(
[1,0]<stdout>:                        ^^^^^^^^^^^^
[1,0]<stdout>:  File "/home/users/industry/ai-hpc/apacsc34/scratch/tanathep/py312/lib/python3.12/site-packages/sglang/srt/model_executor/model_runner.py", line 213, in __init__
[1,0]<stdout>:    self.model_specific_adjustment()
[1,0]<stdout>:  File "/home/users/industry/ai-hpc/apacsc34/scratch/tanathep/py312/lib/python3.12/site-packages/sglang/srt/model_executor/model_runner.py", line 499, in model_specific_adjustment
[1,0]<stdout>:    self.init_double_sparsity_channel_config(server_args.ds_heavy_channel_type)
[1,0]<stdout>:  File "/home/users/industry/ai-hpc/apacsc34/scratch/tanathep/py312/lib/python3.12/site-packages/sglang/srt/model_executor/model_runner.py", line 1581, in init_double_sparsity_channel_config
[1,0]<stdout>:    with open(self.server_args.ds_channel_config_path, "r") as f:
[1,0]<stdout>:         ^^^^^^^^^^^^^^^^^^^^^^^^^^^^^^^^^^^^^^^^^^^^^^^^^^
[1,0]<stdout>:TypeError: expected str, bytes or os.PathLike object, not NoneType
[1,0]<stdout>:
[1,0]<stdout>:[2025-10-12 02:27:58 DP0 TP1] Scheduler hit an exception: Traceback (most recent call last):
[1,0]<stdout>:  File "/home/users/industry/ai-hpc/apacsc34/scratch/tanathep/py312/lib/python3.12/site-packages/sglang/srt/managers/scheduler.py", line 2555, in run_scheduler_process
[1,0]<stdout>:    scheduler = Scheduler(
[1,0]<stdout>:                ^^^^^^^^^^
[1,0]<stdout>:  File "/home/users/industry/ai-hpc/apacsc34/scratch/tanathep/py312/lib/python3.12/site-packages/sglang/srt/managers/scheduler.py", line 315, in __init__
[1,0]<stdout>:    self.tp_worker = TpWorkerClass(
[1,0]<stdout>:                     ^^^^^^^^^^^^^^
[1,0]<stdout>:  File "/home/users/industry/ai-hpc/apacsc34/scratch/tanathep/py312/lib/python3.12/site-packages/sglang/srt/managers/tp_worker.py", line 84, in __init__
[1,0]<stdout>:    self.model_runner = ModelRunner(
[1,0]<stdout>:                        ^^^^^^^^^^^^
[1,0]<stdout>:  File "/home/users/industry/ai-hpc/apacsc34/scratch/tanathep/py312/lib/python3.12/site-packages/sglang/srt/model_executor/model_runner.py", line 213, in __init__
[1,0]<stdout>:    self.model_specific_adjustment()
[1,0]<stdout>:  File "/home/users/industry/ai-hpc/apacsc34/scratch/tanathep/py312/lib/python3.12/site-packages/sglang/srt/model_executor/model_runner.py", line 499, in model_specific_adjustment
[1,0]<stdout>:    self.init_double_sparsity_channel_config(server_args.ds_heavy_channel_type)
[1,0]<stdout>:  File "/home/users/industry/ai-hpc/apacsc34/scratch/tanathep/py312/lib/python3.12/site-packages/sglang/srt/model_executor/model_runner.py", line 1581, in init_double_sparsity_channel_config
[1,0]<stdout>:    with open(self.server_args.ds_channel_config_path, "r") as f:
[1,0]<stdout>:         ^^^^^^^^^^^^^^^^^^^^^^^^^^^^^^^^^^^^^^^^^^^^^^^^^^
[1,0]<stdout>:TypeError: expected str, bytes or os.PathLike object, not NoneType
[1,0]<stdout>:
[1,0]<stdout>:Process Process-1:3:
[1,0]<stdout>:Traceback (most recent call last):
[1,0]<stdout>:  File "/home/users/industry/ai-hpc/apacsc34/scratch/tanathep/py312/lib/python3.12/site-packages/sglang/srt/managers/scheduler.py", line 2555, in run_scheduler_process
[1,0]<stdout>:    scheduler = Scheduler(
[1,0]<stdout>:                ^^^^^^^^^^
[1,0]<stdout>:  File "/home/users/industry/ai-hpc/apacsc34/scratch/tanathep/py312/lib/python3.12/site-packages/sglang/srt/managers/scheduler.py", line 315, in __init__
[1,0]<stdout>:    self.tp_worker = TpWorkerClass(
[1,0]<stdout>:                     ^^^^^^^^^^^^^^
[1,0]<stdout>:  File "/home/users/industry/ai-hpc/apacsc34/scratch/tanathep/py312/lib/python3.12/site-packages/sglang/srt/managers/tp_worker.py", line 84, in __init__
[1,0]<stdout>:    self.model_runner = ModelRunner(
[1,0]<stdout>:                        ^^^^^^^^^^^^
[1,0]<stdout>:  File "/home/users/industry/ai-hpc/apacsc34/scratch/tanathep/py312/lib/python3.12/site-packages/sglang/srt/model_executor/model_runner.py", line 213, in __init__
[1,0]<stdout>:    self.model_specific_adjustment()
[1,0]<stdout>:  File "/home/users/industry/ai-hpc/apacsc34/scratch/tanathep/py312/lib/python3.12/site-packages/sglang/srt/model_executor/model_runner.py", line 499, in model_specific_adjustment
[1,0]<stdout>:    self.init_double_sparsity_channel_config(server_args.ds_heavy_channel_type)
[1,0]<stdout>:  File "/home/users/industry/ai-hpc/apacsc34/scratch/tanathep/py312/lib/python3.12/site-packages/sglang/srt/model_executor/model_runner.py", line 1581, in init_double_sparsity_channel_config
[1,0]<stdout>:    with open(self.server_args.ds_channel_config_path, "r") as f:
[1,0]<stdout>:         ^^^^^^^^^^^^^^^^^^^^^^^^^^^^^^^^^^^^^^^^^^^^^^^^^^
[1,0]<stdout>:TypeError: expected str, bytes or os.PathLike object, not NoneType
[1,0]<stdout>:
[1,0]<stdout>:During handling of the above exception, another exception occurred:
[1,0]<stdout>:
[1,0]<stdout>:Traceback (most recent call last):
[1,0]<stdout>:  File "/home/users/industry/ai-hpc/apacsc34/scratch/tanathep/py312/lib/python3.12/site-packages/psutil/__init__.py", line 1259, in _send_signal
[1,0]<stdout>:    os.kill(pid, sig)
[1,0]<stdout>:PermissionError: [Errno 1] Operation not permitted
[1,0]<stdout>:
[1,0]<stdout>:The above exception was the direct cause of the following exception:
[1,0]<stdout>:
[1,0]<stdout>:Traceback (most recent call last):
[1,0]<stdout>:  File "/home/users/industry/ai-hpc/apacsc34/scratch/tanathep/py312/lib/python3.12/multiprocessing/process.py", line 314, in _bootstrap
[1,0]<stdout>:    self.run()
[1,0]<stdout>:  File "/home/users/industry/ai-hpc/apacsc34/scratch/tanathep/py312/lib/python3.12/multiprocessing/process.py", line 108, in run
[1,0]<stdout>:    self._target(*self._args, **self._kwargs)
[1,0]<stdout>:  File "/home/users/industry/ai-hpc/apacsc34/scratch/tanathep/py312/lib/python3.12/site-packages/sglang/srt/managers/scheduler.py", line 2596, in run_scheduler_process
[1,0]<stdout>:    parent_process.send_signal(signal.SIGQUIT)
[1,0]<stdout>:  File "/home/users/industry/ai-hpc/apacsc34/scratch/tanathep/py312/lib/python3.12/site-packages/psutil/__init__.py", line 1277, in send_signal
[1,0]<stdout>:    self._send_signal(sig)
[1,0]<stdout>:  File "/home/users/industry/ai-hpc/apacsc34/scratch/tanathep/py312/lib/python3.12/site-packages/psutil/__init__.py", line 1268, in _send_signal
[1,0]<stdout>:    raise AccessDenied(pid, name) from err
[1,0]<stdout>:psutil.AccessDenied: (pid=1)
[1,0]<stdout>:[2025-10-12 02:27:58 DP0 TP6] Scheduler hit an exception: Traceback (most recent call last):
[1,0]<stdout>:  File "/home/users/industry/ai-hpc/apacsc34/scratch/tanathep/py312/lib/python3.12/site-packages/sglang/srt/managers/scheduler.py", line 2555, in run_scheduler_process
[1,0]<stdout>:    scheduler = Scheduler(
[1,0]<stdout>:                ^^^^^^^^^^
[1,0]<stdout>:  File "/home/users/industry/ai-hpc/apacsc34/scratch/tanathep/py312/lib/python3.12/site-packages/sglang/srt/managers/scheduler.py", line 315, in __init__
[1,0]<stdout>:    self.tp_worker = TpWorkerClass(
[1,0]<stdout>:                     ^^^^^^^^^^^^^^
[1,0]<stdout>:  File "/home/users/industry/ai-hpc/apacsc34/scratch/tanathep/py312/lib/python3.12/site-packages/sglang/srt/managers/tp_worker.py", line 84, in __init__
[1,0]<stdout>:    self.model_runner = ModelRunner(
[1,0]<stdout>:                        ^^^^^^^^^^^^
[1,0]<stdout>:  File "/home/users/industry/ai-hpc/apacsc34/scratch/tanathep/py312/lib/python3.12/site-packages/sglang/srt/model_executor/model_runner.py", line 213, in __init__
[1,0]<stdout>:    self.model_specific_adjustment()
[1,0]<stdout>:  File "/home/users/industry/ai-hpc/apacsc34/scratch/tanathep/py312/lib/python3.12/site-packages/sglang/srt/model_executor/model_runner.py", line 499, in model_specific_adjustment
[1,0]<stdout>:    self.init_double_sparsity_channel_config(server_args.ds_heavy_channel_type)
[1,0]<stdout>:  File "/home/users/industry/ai-hpc/apacsc34/scratch/tanathep/py312/lib/python3.12/site-packages/sglang/srt/model_executor/model_runner.py", line 1581, in init_double_sparsity_channel_config
[1,0]<stdout>:    with open(self.server_args.ds_channel_config_path, "r") as f:
[1,0]<stdout>:         ^^^^^^^^^^^^^^^^^^^^^^^^^^^^^^^^^^^^^^^^^^^^^^^^^^
[1,0]<stdout>:TypeError: expected str, bytes or os.PathLike object, not NoneType
[1,0]<stdout>:
[1,0]<stdout>:Process Process-1:8:
[1,0]<stdout>:Traceback (most recent call last):
[1,0]<stdout>:  File "/home/users/industry/ai-hpc/apacsc34/scratch/tanathep/py312/lib/python3.12/site-packages/sglang/srt/managers/scheduler.py", line 2555, in run_scheduler_process
[1,0]<stdout>:    scheduler = Scheduler(
[1,0]<stdout>:                ^^^^^^^^^^
[1,0]<stdout>:  File "/home/users/industry/ai-hpc/apacsc34/scratch/tanathep/py312/lib/python3.12/site-packages/sglang/srt/managers/scheduler.py", line 315, in __init__
[1,0]<stdout>:    self.tp_worker = TpWorkerClass(
[1,0]<stdout>:                     ^^^^^^^^^^^^^^
[1,0]<stdout>:  File "/home/users/industry/ai-hpc/apacsc34/scratch/tanathep/py312/lib/python3.12/site-packages/sglang/srt/managers/tp_worker.py", line 84, in __init__
[1,0]<stdout>:    self.model_runner = ModelRunner(
[1,0]<stdout>:                        ^^^^^^^^^^^^
[1,0]<stdout>:  File "/home/users/industry/ai-hpc/apacsc34/scratch/tanathep/py312/lib/python3.12/site-packages/sglang/srt/model_executor/model_runner.py", line 213, in __init__
[1,0]<stdout>:    self.model_specific_adjustment()
[1,0]<stdout>:  File "/home/users/industry/ai-hpc/apacsc34/scratch/tanathep/py312/lib/python3.12/site-packages/sglang/srt/model_executor/model_runner.py", line 499, in model_specific_adjustment
[1,0]<stdout>:    self.init_double_sparsity_channel_config(server_args.ds_heavy_channel_type)
[1,0]<stdout>:  File "/home/users/industry/ai-hpc/apacsc34/scratch/tanathep/py312/lib/python3.12/site-packages/sglang/srt/model_executor/model_runner.py", line 1581, in init_double_sparsity_channel_config
[1,0]<stdout>:    with open(self.server_args.ds_channel_config_path, "r") as f:
[1,0]<stdout>:         ^^^^^^^^^^^^^^^^^^^^^^^^^^^^^^^^^^^^^^^^^^^^^^^^^^
[1,0]<stdout>:TypeError: expected str, bytes or os.PathLike object, not NoneType
[1,0]<stdout>:
[1,0]<stdout>:During handling of the above exception, another exception occurred:
[1,0]<stdout>:
[1,0]<stdout>:Traceback (most recent call last):
[1,0]<stdout>:  File "/home/users/industry/ai-hpc/apacsc34/scratch/tanathep/py312/lib/python3.12/site-packages/psutil/__init__.py", line 1259, in _send_signal
[1,0]<stdout>:    os.kill(pid, sig)
[1,0]<stdout>:PermissionError: [Errno 1] Operation not permitted
[1,0]<stdout>:
[1,0]<stdout>:The above exception was the direct cause of the following exception:
[1,0]<stdout>:
[1,0]<stdout>:Traceback (most recent call last):
[1,0]<stdout>:  File "/home/users/industry/ai-hpc/apacsc34/scratch/tanathep/py312/lib/python3.12/multiprocessing/process.py", line 314, in _bootstrap
[1,0]<stdout>:    self.run()
[1,0]<stdout>:  File "/home/users/industry/ai-hpc/apacsc34/scratch/tanathep/py312/lib/python3.12/multiprocessing/process.py", line 108, in run
[1,0]<stdout>:    self._target(*self._args, **self._kwargs)
[1,0]<stdout>:  File "/home/users/industry/ai-hpc/apacsc34/scratch/tanathep/py312/lib/python3.12/site-packages/sglang/srt/managers/scheduler.py", line 2596, in run_scheduler_process
[1,0]<stdout>:    parent_process.send_signal(signal.SIGQUIT)
[1,0]<stdout>:  File "/home/users/industry/ai-hpc/apacsc34/scratch/tanathep/py312/lib/python3.12/site-packages/psutil/__init__.py", line 1277, in send_signal
[1,0]<stdout>:    self._send_signal(sig)
[1,0]<stdout>:  File "/home/users/industry/ai-hpc/apacsc34/scratch/tanathep/py312/lib/python3.12/site-packages/psutil/__init__.py", line 1268, in _send_signal
[1,0]<stdout>:    raise AccessDenied(pid, name) from err
[1,0]<stdout>:psutil.AccessDenied: (pid=1)
[1,1]<stdout>:[2025-10-12 02:27:59 DP1 TP9] Scheduler hit an exception: Traceback (most recent call last):
[1,1]<stdout>:  File "/home/users/industry/ai-hpc/apacsc34/scratch/tanathep/py312/lib/python3.12/site-packages/sglang/srt/managers/scheduler.py", line 2555, in run_scheduler_process
[1,1]<stdout>:    scheduler = Scheduler(
[1,1]<stdout>:                ^^^^^^^^^^
[1,1]<stdout>:  File "/home/users/industry/ai-hpc/apacsc34/scratch/tanathep/py312/lib/python3.12/site-packages/sglang/srt/managers/scheduler.py", line 315, in __init__
[1,1]<stdout>:    self.tp_worker = TpWorkerClass(
[1,1]<stdout>:                     ^^^^^^^^^^^^^^
[1,1]<stdout>:  File "/home/users/industry/ai-hpc/apacsc34/scratch/tanathep/py312/lib/python3.12/site-packages/sglang/srt/managers/tp_worker.py", line 84, in __init__
[1,1]<stdout>:    self.model_runner = ModelRunner(
[1,1]<stdout>:                        ^^^^^^^^^^^^
[1,1]<stdout>:  File "/home/users/industry/ai-hpc/apacsc34/scratch/tanathep/py312/lib/python3.12/site-packages/sglang/srt/model_executor/model_runner.py", line 213, in __init__
[1,1]<stdout>:    self.model_specific_adjustment()
[1,1]<stdout>:  File "/home/users/industry/ai-hpc/apacsc34/scratch/tanathep/py312/lib/python3.12/site-packages/sglang/srt/model_executor/model_runner.py", line 499, in model_specific_adjustment
[1,1]<stdout>:    self.init_double_sparsity_channel_config(server_args.ds_heavy_channel_type)
[1,1]<stdout>:  File "/home/users/industry/ai-hpc/apacsc34/scratch/tanathep/py312/lib/python3.12/site-packages/sglang/srt/model_executor/model_runner.py", line 1581, in init_double_sparsity_channel_config
[1,1]<stdout>:    with open(self.server_args.ds_channel_config_path, "r") as f:
[1,1]<stdout>:         ^^^^^^^^^^^^^^^^^^^^^^^^^^^^^^^^^^^^^^^^^^^^^^^^^^
[1,1]<stdout>:TypeError: expected str, bytes or os.PathLike object, not NoneType
[1,1]<stdout>:
[1,1]<stdout>:Process Process-1:3:
[1,1]<stdout>:Traceback (most recent call last):
[1,1]<stdout>:  File "/home/users/industry/ai-hpc/apacsc34/scratch/tanathep/py312/lib/python3.12/site-packages/sglang/srt/managers/scheduler.py", line 2555, in run_scheduler_process
[1,1]<stdout>:    scheduler = Scheduler(
[1,1]<stdout>:                ^^^^^^^^^^
[1,1]<stdout>:  File "/home/users/industry/ai-hpc/apacsc34/scratch/tanathep/py312/lib/python3.12/site-packages/sglang/srt/managers/scheduler.py", line 315, in __init__
[1,1]<stdout>:    self.tp_worker = TpWorkerClass(
[1,1]<stdout>:                     ^^^^^^^^^^^^^^
[1,1]<stdout>:  File "/home/users/industry/ai-hpc/apacsc34/scratch/tanathep/py312/lib/python3.12/site-packages/sglang/srt/managers/tp_worker.py", line 84, in __init__
[1,1]<stdout>:    self.model_runner = ModelRunner(
[1,1]<stdout>:                        ^^^^^^^^^^^^
[1,1]<stdout>:  File "/home/users/industry/ai-hpc/apacsc34/scratch/tanathep/py312/lib/python3.12/site-packages/sglang/srt/model_executor/model_runner.py", line 213, in __init__
[1,1]<stdout>:    self.model_specific_adjustment()
[1,1]<stdout>:  File "/home/users/industry/ai-hpc/apacsc34/scratch/tanathep/py312/lib/python3.12/site-packages/sglang/srt/model_executor/model_runner.py", line 499, in model_specific_adjustment
[1,1]<stdout>:    self.init_double_sparsity_channel_config(server_args.ds_heavy_channel_type)
[1,1]<stdout>:  File "/home/users/industry/ai-hpc/apacsc34/scratch/tanathep/py312/lib/python3.12/site-packages/sglang/srt/model_executor/model_runner.py", line 1581, in init_double_sparsity_channel_config
[1,1]<stdout>:    with open(self.server_args.ds_channel_config_path, "r") as f:
[1,1]<stdout>:         ^^^^^^^^^^^^^^^^^^^^^^^^^^^^^^^^^^^^^^^^^^^^^^^^^^
[1,1]<stdout>:TypeError: expected str, bytes or os.PathLike object, not NoneType
[1,1]<stdout>:
[1,1]<stdout>:During handling of the above exception, another exception occurred:
[1,1]<stdout>:
[1,1]<stdout>:Traceback (most recent call last):
[1,1]<stdout>:  File "/home/users/industry/ai-hpc/apacsc34/scratch/tanathep/py312/lib/python3.12/site-packages/psutil/__init__.py", line 1259, in _send_signal
[1,1]<stdout>:    os.kill(pid, sig)
[1,1]<stdout>:PermissionError: [Errno 1] Operation not permitted
[1,1]<stdout>:
[1,1]<stdout>:The above exception was the direct cause of the following exception:
[1,1]<stdout>:
[1,1]<stdout>:Traceback (most recent call last):
[1,1]<stdout>:  File "/home/users/industry/ai-hpc/apacsc34/scratch/tanathep/py312/lib/python3.12/multiprocessing/process.py", line 314, in _bootstrap
[1,1]<stdout>:    self.run()
[1,1]<stdout>:  File "/home/users/industry/ai-hpc/apacsc34/scratch/tanathep/py312/lib/python3.12/multiprocessing/process.py", line 108, in run
[1,1]<stdout>:    self._target(*self._args, **self._kwargs)
[1,1]<stdout>:  File "/home/users/industry/ai-hpc/apacsc34/scratch/tanathep/py312/lib/python3.12/site-packages/sglang/srt/managers/scheduler.py", line 2596, in run_scheduler_process
[1,1]<stdout>:    parent_process.send_signal(signal.SIGQUIT)
[1,1]<stdout>:  File "/home/users/industry/ai-hpc/apacsc34/scratch/tanathep/py312/lib/python3.12/site-packages/psutil/__init__.py", line 1277, in send_signal
[1,1]<stdout>:    self._send_signal(sig)
[1,1]<stdout>:  File "/home/users/industry/ai-hpc/apacsc34/scratch/tanathep/py312/lib/python3.12/site-packages/psutil/__init__.py", line 1268, in _send_signal
[1,1]<stdout>:    raise AccessDenied(pid, name) from err
[1,1]<stdout>:psutil.AccessDenied: (pid=1)
[1,1]<stdout>:[2025-10-12 02:27:59 DP1 TP15] Scheduler hit an exception: Traceback (most recent call last):
[1,1]<stdout>:  File "/home/users/industry/ai-hpc/apacsc34/scratch/tanathep/py312/lib/python3.12/site-packages/sglang/srt/managers/scheduler.py", line 2555, in run_scheduler_process
[1,1]<stdout>:    scheduler = Scheduler(
[1,1]<stdout>:                ^^^^^^^^^^
[1,1]<stdout>:  File "/home/users/industry/ai-hpc/apacsc34/scratch/tanathep/py312/lib/python3.12/site-packages/sglang/srt/managers/scheduler.py", line 315, in __init__
[1,1]<stdout>:    self.tp_worker = TpWorkerClass(
[1,1]<stdout>:                     ^^^^^^^^^^^^^^
[1,1]<stdout>:  File "/home/users/industry/ai-hpc/apacsc34/scratch/tanathep/py312/lib/python3.12/site-packages/sglang/srt/managers/tp_worker.py", line 84, in __init__
[1,1]<stdout>:    self.model_runner = ModelRunner(
[1,1]<stdout>:                        ^^^^^^^^^^^^
[1,1]<stdout>:  File "/home/users/industry/ai-hpc/apacsc34/scratch/tanathep/py312/lib/python3.12/site-packages/sglang/srt/model_executor/model_runner.py", line 213, in __init__
[1,1]<stdout>:    self.model_specific_adjustment()
[1,1]<stdout>:  File "/home/users/industry/ai-hpc/apacsc34/scratch/tanathep/py312/lib/python3.12/site-packages/sglang/srt/model_executor/model_runner.py", line 499, in model_specific_adjustment
[1,1]<stdout>:    self.init_double_sparsity_channel_config(server_args.ds_heavy_channel_type)
[1,1]<stdout>:  File "/home/users/industry/ai-hpc/apacsc34/scratch/tanathep/py312/lib/python3.12/site-packages/sglang/srt/model_executor/model_runner.py", line 1581, in init_double_sparsity_channel_config
[1,1]<stdout>:    with open(self.server_args.ds_channel_config_path, "r") as f:
[1,1]<stdout>:         ^^^^^^^^^^^^^^^^^^^^^^^^^^^^^^^^^^^^^^^^^^^^^^^^^^
[1,1]<stdout>:TypeError: expected str, bytes or os.PathLike object, not NoneType
[1,1]<stdout>:
[1,1]<stdout>:Process Process-1:9:
[1,1]<stdout>:Traceback (most recent call last):
[1,1]<stdout>:  File "/home/users/industry/ai-hpc/apacsc34/scratch/tanathep/py312/lib/python3.12/site-packages/sglang/srt/managers/scheduler.py", line 2555, in run_scheduler_process
[1,1]<stdout>:    scheduler = Scheduler(
[1,1]<stdout>:                ^^^^^^^^^^
[1,1]<stdout>:  File "/home/users/industry/ai-hpc/apacsc34/scratch/tanathep/py312/lib/python3.12/site-packages/sglang/srt/managers/scheduler.py", line 315, in __init__
[1,1]<stdout>:    self.tp_worker = TpWorkerClass(
[1,1]<stdout>:                     ^^^^^^^^^^^^^^
[1,1]<stdout>:  File "/home/users/industry/ai-hpc/apacsc34/scratch/tanathep/py312/lib/python3.12/site-packages/sglang/srt/managers/tp_worker.py", line 84, in __init__
[1,1]<stdout>:    self.model_runner = ModelRunner(
[1,1]<stdout>:                        ^^^^^^^^^^^^
[1,1]<stdout>:  File "/home/users/industry/ai-hpc/apacsc34/scratch/tanathep/py312/lib/python3.12/site-packages/sglang/srt/model_executor/model_runner.py", line 213, in __init__
[1,1]<stdout>:    self.model_specific_adjustment()
[1,1]<stdout>:  File "/home/users/industry/ai-hpc/apacsc34/scratch/tanathep/py312/lib/python3.12/site-packages/sglang/srt/model_executor/model_runner.py", line 499, in model_specific_adjustment
[1,1]<stdout>:    self.init_double_sparsity_channel_config(server_args.ds_heavy_channel_type)
[1,1]<stdout>:  File "/home/users/industry/ai-hpc/apacsc34/scratch/tanathep/py312/lib/python3.12/site-packages/sglang/srt/model_executor/model_runner.py", line 1581, in init_double_sparsity_channel_config
[1,1]<stdout>:    with open(self.server_args.ds_channel_config_path, "r") as f:
[1,1]<stdout>:         ^^^^^^^^^^^^^^^^^^^^^^^^^^^^^^^^^^^^^^^^^^^^^^^^^^
[1,1]<stdout>:TypeError: expected str, bytes or os.PathLike object, not NoneType
[1,1]<stdout>:
[1,1]<stdout>:During handling of the above exception, another exception occurred:
[1,1]<stdout>:
[1,1]<stdout>:Traceback (most recent call last):
[1,1]<stdout>:  File "/home/users/industry/ai-hpc/apacsc34/scratch/tanathep/py312/lib/python3.12/site-packages/psutil/__init__.py", line 1259, in _send_signal
[1,1]<stdout>:    os.kill(pid, sig)
[1,1]<stdout>:PermissionError: [Errno 1] Operation not permitted
[1,1]<stdout>:
[1,1]<stdout>:The above exception was the direct cause of the following exception:
[1,1]<stdout>:
[1,1]<stdout>:Traceback (most recent call last):
[1,1]<stdout>:  File "/home/users/industry/ai-hpc/apacsc34/scratch/tanathep/py312/lib/python3.12/multiprocessing/process.py", line 314, in _bootstrap
[1,1]<stdout>:    self.run()
[1,1]<stdout>:  File "/home/users/industry/ai-hpc/apacsc34/scratch/tanathep/py312/lib/python3.12/multiprocessing/process.py", line 108, in run
[1,1]<stdout>:    self._target(*self._args, **self._kwargs)
[1,1]<stdout>:  File "/home/users/industry/ai-hpc/apacsc34/scratch/tanathep/py312/lib/python3.12/site-packages/sglang/srt/managers/scheduler.py", line 2596, in run_scheduler_process
[1,1]<stdout>:    parent_process.send_signal(signal.SIGQUIT)
[1,1]<stdout>:  File "/home/users/industry/ai-hpc/apacsc34/scratch/tanathep/py312/lib/python3.12/site-packages/psutil/__init__.py", line 1277, in send_signal
[1,1]<stdout>:    self._send_signal(sig)
[1,1]<stdout>:  File "/home/users/industry/ai-hpc/apacsc34/scratch/tanathep/py312/lib/python3.12/site-packages/psutil/__init__.py", line 1268, in _send_signal
[1,1]<stdout>:    raise AccessDenied(pid, name) from err
[1,1]<stdout>:psutil.AccessDenied: (pid=1)
[1,1]<stdout>:[2025-10-12 02:27:59 DP1 TP14] Scheduler hit an exception: Traceback (most recent call last):
[1,1]<stdout>:  File "/home/users/industry/ai-hpc/apacsc34/scratch/tanathep/py312/lib/python3.12/site-packages/sglang/srt/managers/scheduler.py", line 2555, in run_scheduler_process
[1,1]<stdout>:    scheduler = Scheduler(
[1,1]<stdout>:                ^^^^^^^^^^
[1,1]<stdout>:  File "/home/users/industry/ai-hpc/apacsc34/scratch/tanathep/py312/lib/python3.12/site-packages/sglang/srt/managers/scheduler.py", line 315, in __init__
[1,1]<stdout>:    self.tp_worker = TpWorkerClass(
[1,1]<stdout>:                     ^^^^^^^^^^^^^^
[1,1]<stdout>:  File "/home/users/industry/ai-hpc/apacsc34/scratch/tanathep/py312/lib/python3.12/site-packages/sglang/srt/managers/tp_worker.py", line 84, in __init__
[1,1]<stdout>:    self.model_runner = ModelRunner(
[1,1]<stdout>:                        ^^^^^^^^^^^^
[1,1]<stdout>:  File "/home/users/industry/ai-hpc/apacsc34/scratch/tanathep/py312/lib/python3.12/site-packages/sglang/srt/model_executor/model_runner.py", line 213, in __init__
[1,1]<stdout>:    self.model_specific_adjustment()
[1,1]<stdout>:  File "/home/users/industry/ai-hpc/apacsc34/scratch/tanathep/py312/lib/python3.12/site-packages/sglang/srt/model_executor/model_runner.py", line 499, in model_specific_adjustment
[1,1]<stdout>:    self.init_double_sparsity_channel_config(server_args.ds_heavy_channel_type)
[1,1]<stdout>:  File "/home/users/industry/ai-hpc/apacsc34/scratch/tanathep/py312/lib/python3.12/site-packages/sglang/srt/model_executor/model_runner.py", line 1581, in init_double_sparsity_channel_config
[1,1]<stdout>:    with open(self.server_args.ds_channel_config_path, "r") as f:
[1,1]<stdout>:         ^^^^^^^^^^^^^^^^^^^^^^^^^^^^^^^^^^^^^^^^^^^^^^^^^^
[1,1]<stdout>:TypeError: expected str, bytes or os.PathLike object, not NoneType
[1,1]<stdout>:
[1,1]<stdout>:Process Process-1:8:
[1,1]<stdout>:Traceback (most recent call last):
[1,1]<stdout>:  File "/home/users/industry/ai-hpc/apacsc34/scratch/tanathep/py312/lib/python3.12/site-packages/sglang/srt/managers/scheduler.py", line 2555, in run_scheduler_process
[1,1]<stdout>:    scheduler = Scheduler(
[1,1]<stdout>:                ^^^^^^^^^^
[1,1]<stdout>:  File "/home/users/industry/ai-hpc/apacsc34/scratch/tanathep/py312/lib/python3.12/site-packages/sglang/srt/managers/scheduler.py", line 315, in __init__
[1,1]<stdout>:    self.tp_worker = TpWorkerClass(
[1,1]<stdout>:                     ^^^^^^^^^^^^^^
[1,1]<stdout>:  File "/home/users/industry/ai-hpc/apacsc34/scratch/tanathep/py312/lib/python3.12/site-packages/sglang/srt/managers/tp_worker.py", line 84, in __init__
[1,1]<stdout>:    self.model_runner = ModelRunner(
[1,1]<stdout>:                        ^^^^^^^^^^^^
[1,1]<stdout>:  File "/home/users/industry/ai-hpc/apacsc34/scratch/tanathep/py312/lib/python3.12/site-packages/sglang/srt/model_executor/model_runner.py", line 213, in __init__
[1,1]<stdout>:    self.model_specific_adjustment()
[1,1]<stdout>:  File "/home/users/industry/ai-hpc/apacsc34/scratch/tanathep/py312/lib/python3.12/site-packages/sglang/srt/model_executor/model_runner.py", line 499, in model_specific_adjustment
[1,1]<stdout>:    self.init_double_sparsity_channel_config(server_args.ds_heavy_channel_type)
[1,1]<stdout>:  File "/home/users/industry/ai-hpc/apacsc34/scratch/tanathep/py312/lib/python3.12/site-packages/sglang/srt/model_executor/model_runner.py", line 1581, in init_double_sparsity_channel_config
[1,1]<stdout>:    with open(self.server_args.ds_channel_config_path, "r") as f:
[1,1]<stdout>:         ^^^^^^^^^^^^^^^^^^^^^^^^^^^^^^^^^^^^^^^^^^^^^^^^^^
[1,1]<stdout>:TypeError: expected str, bytes or os.PathLike object, not NoneType
[1,1]<stdout>:
[1,1]<stdout>:During handling of the above exception, another exception occurred:
[1,1]<stdout>:
[1,1]<stdout>:Traceback (most recent call last):
[1,1]<stdout>:  File "/home/users/industry/ai-hpc/apacsc34/scratch/tanathep/py312/lib/python3.12/site-packages/psutil/__init__.py", line 1259, in _send_signal
[1,1]<stdout>:    os.kill(pid, sig)
[1,1]<stdout>:PermissionError: [Errno 1] Operation not permitted
[1,1]<stdout>:
[1,1]<stdout>:The above exception was the direct cause of the following exception:
[1,1]<stdout>:
[1,1]<stdout>:Traceback (most recent call last):
[1,1]<stdout>:  File "/home/users/industry/ai-hpc/apacsc34/scratch/tanathep/py312/lib/python3.12/multiprocessing/process.py", line 314, in _bootstrap
[1,1]<stdout>:    self.run()
[1,1]<stdout>:  File "/home/users/industry/ai-hpc/apacsc34/scratch/tanathep/py312/lib/python3.12/multiprocessing/process.py", line 108, in run
[1,1]<stdout>:    self._target(*self._args, **self._kwargs)
[1,1]<stdout>:  File "/home/users/industry/ai-hpc/apacsc34/scratch/tanathep/py312/lib/python3.12/site-packages/sglang/srt/managers/scheduler.py", line 2596, in run_scheduler_process
[1,1]<stdout>:    parent_process.send_signal(signal.SIGQUIT)
[1,1]<stdout>:  File "/home/users/industry/ai-hpc/apacsc34/scratch/tanathep/py312/lib/python3.12/site-packages/psutil/__init__.py", line 1277, in send_signal
[1,1]<stdout>:    self._send_signal(sig)
[1,1]<stdout>:  File "/home/users/industry/ai-hpc/apacsc34/scratch/tanathep/py312/lib/python3.12/site-packages/psutil/__init__.py", line 1268, in _send_signal
[1,1]<stdout>:    raise AccessDenied(pid, name) from err
[1,1]<stdout>:psutil.AccessDenied: (pid=1)
[1,1]<stdout>:[2025-10-12 02:27:59 DP1 TP8] Scheduler hit an exception: Traceback (most recent call last):
[1,1]<stdout>:  File "/home/users/industry/ai-hpc/apacsc34/scratch/tanathep/py312/lib/python3.12/site-packages/sglang/srt/managers/scheduler.py", line 2555, in run_scheduler_process
[1,1]<stdout>:    scheduler = Scheduler(
[1,1]<stdout>:                ^^^^^^^^^^
[1,1]<stdout>:  File "/home/users/industry/ai-hpc/apacsc34/scratch/tanathep/py312/lib/python3.12/site-packages/sglang/srt/managers/scheduler.py", line 315, in __init__
[1,1]<stdout>:    self.tp_worker = TpWorkerClass(
[1,1]<stdout>:                     ^^^^^^^^^^^^^^
[1,1]<stdout>:  File "/home/users/industry/ai-hpc/apacsc34/scratch/tanathep/py312/lib/python3.12/site-packages/sglang/srt/managers/tp_worker.py", line 84, in __init__
[1,1]<stdout>:    self.model_runner = ModelRunner(
[1,1]<stdout>:                        ^^^^^^^^^^^^
[1,1]<stdout>:  File "/home/users/industry/ai-hpc/apacsc34/scratch/tanathep/py312/lib/python3.12/site-packages/sglang/srt/model_executor/model_runner.py", line 213, in __init__
[1,1]<stdout>:    self.model_specific_adjustment()
[1,1]<stdout>:  File "/home/users/industry/ai-hpc/apacsc34/scratch/tanathep/py312/lib/python3.12/site-packages/sglang/srt/model_executor/model_runner.py", line 499, in model_specific_adjustment
[1,1]<stdout>:    self.init_double_sparsity_channel_config(server_args.ds_heavy_channel_type)
[1,1]<stdout>:  File "/home/users/industry/ai-hpc/apacsc34/scratch/tanathep/py312/lib/python3.12/site-packages/sglang/srt/model_executor/model_runner.py", line 1581, in init_double_sparsity_channel_config
[1,1]<stdout>:    with open(self.server_args.ds_channel_config_path, "r") as f:
[1,1]<stdout>:         ^^^^^^^^^^^^^^^^^^^^^^^^^^^^^^^^^^^^^^^^^^^^^^^^^^
[1,1]<stdout>:TypeError: expected str, bytes or os.PathLike object, not NoneType
[1,1]<stdout>:
[1,1]<stdout>:Process Process-1:2:
[1,1]<stdout>:Traceback (most recent call last):
[1,1]<stdout>:  File "/home/users/industry/ai-hpc/apacsc34/scratch/tanathep/py312/lib/python3.12/site-packages/sglang/srt/managers/scheduler.py", line 2555, in run_scheduler_process
[1,1]<stdout>:    scheduler = Scheduler(
[1,1]<stdout>:                ^^^^^^^^^^
[1,1]<stdout>:  File "/home/users/industry/ai-hpc/apacsc34/scratch/tanathep/py312/lib/python3.12/site-packages/sglang/srt/managers/scheduler.py", line 315, in __init__
[1,1]<stdout>:    self.tp_worker = TpWorkerClass(
[1,1]<stdout>:                     ^^^^^^^^^^^^^^
[1,1]<stdout>:  File "/home/users/industry/ai-hpc/apacsc34/scratch/tanathep/py312/lib/python3.12/site-packages/sglang/srt/managers/tp_worker.py", line 84, in __init__
[1,1]<stdout>:    self.model_runner = ModelRunner(
[1,1]<stdout>:                        ^^^^^^^^^^^^
[1,1]<stdout>:  File "/home/users/industry/ai-hpc/apacsc34/scratch/tanathep/py312/lib/python3.12/site-packages/sglang/srt/model_executor/model_runner.py", line 213, in __init__
[1,1]<stdout>:    self.model_specific_adjustment()
[1,1]<stdout>:  File "/home/users/industry/ai-hpc/apacsc34/scratch/tanathep/py312/lib/python3.12/site-packages/sglang/srt/model_executor/model_runner.py", line 499, in model_specific_adjustment
[1,1]<stdout>:    self.init_double_sparsity_channel_config(server_args.ds_heavy_channel_type)
[1,1]<stdout>:  File "/home/users/industry/ai-hpc/apacsc34/scratch/tanathep/py312/lib/python3.12/site-packages/sglang/srt/model_executor/model_runner.py", line 1581, in init_double_sparsity_channel_config
[1,1]<stdout>:    with open(self.server_args.ds_channel_config_path, "r") as f:
[1,1]<stdout>:         ^^^^^^^^^^^^^^^^^^^^^^^^^^^^^^^^^^^^^^^^^^^^^^^^^^
[1,1]<stdout>:TypeError: expected str, bytes or os.PathLike object, not NoneType
[1,1]<stdout>:
[1,1]<stdout>:During handling of the above exception, another exception occurred:
[1,1]<stdout>:
[1,1]<stdout>:Traceback (most recent call last):
[1,1]<stdout>:  File "/home/users/industry/ai-hpc/apacsc34/scratch/tanathep/py312/lib/python3.12/site-packages/psutil/__init__.py", line 1259, in _send_signal
[1,1]<stdout>:    os.kill(pid, sig)
[1,1]<stdout>:PermissionError: [Errno 1] Operation not permitted
[1,1]<stdout>:
[1,1]<stdout>:The above exception was the direct cause of the following exception:
[1,1]<stdout>:
[1,1]<stdout>:Traceback (most recent call last):
[1,1]<stdout>:  File "/home/users/industry/ai-hpc/apacsc34/scratch/tanathep/py312/lib/python3.12/multiprocessing/process.py", line 314, in _bootstrap
[1,1]<stdout>:    self.run()
[1,1]<stdout>:  File "/home/users/industry/ai-hpc/apacsc34/scratch/tanathep/py312/lib/python3.12/multiprocessing/process.py", line 108, in run
[1,1]<stdout>:    self._target(*self._args, **self._kwargs)
[1,1]<stdout>:  File "/home/users/industry/ai-hpc/apacsc34/scratch/tanathep/py312/lib/python3.12/site-packages/sglang/srt/managers/scheduler.py", line 2596, in run_scheduler_process
[1,1]<stdout>:    parent_process.send_signal(signal.SIGQUIT)
[1,1]<stdout>:  File "/home/users/industry/ai-hpc/apacsc34/scratch/tanathep/py312/lib/python3.12/site-packages/psutil/__init__.py", line 1277, in send_signal
[1,1]<stdout>:    self._send_signal(sig)
[1,1]<stdout>:  File "/home/users/industry/ai-hpc/apacsc34/scratch/tanathep/py312/lib/python3.12/site-packages/psutil/__init__.py", line 1268, in _send_signal
[1,1]<stdout>:    raise AccessDenied(pid, name) from err
[1,1]<stdout>:psutil.AccessDenied: (pid=1)
[1,1]<stdout>:[2025-10-12 02:27:59 DP1 TP10] Scheduler hit an exception: Traceback (most recent call last):
[1,1]<stdout>:  File "/home/users/industry/ai-hpc/apacsc34/scratch/tanathep/py312/lib/python3.12/site-packages/sglang/srt/managers/scheduler.py", line 2555, in run_scheduler_process
[1,1]<stdout>:    scheduler = Scheduler(
[1,1]<stdout>:                ^^^^^^^^^^
[1,1]<stdout>:  File "/home/users/industry/ai-hpc/apacsc34/scratch/tanathep/py312/lib/python3.12/site-packages/sglang/srt/managers/scheduler.py", line 315, in __init__
[1,1]<stdout>:    self.tp_worker = TpWorkerClass(
[1,1]<stdout>:                     ^^^^^^^^^^^^^^
[1,1]<stdout>:  File "/home/users/industry/ai-hpc/apacsc34/scratch/tanathep/py312/lib/python3.12/site-packages/sglang/srt/managers/tp_worker.py", line 84, in __init__
[1,1]<stdout>:    self.model_runner = ModelRunner(
[1,1]<stdout>:                        ^^^^^^^^^^^^
[1,1]<stdout>:  File "/home/users/industry/ai-hpc/apacsc34/scratch/tanathep/py312/lib/python3.12/site-packages/sglang/srt/model_executor/model_runner.py", line 213, in __init__
[1,1]<stdout>:    self.model_specific_adjustment()
[1,1]<stdout>:  File "/home/users/industry/ai-hpc/apacsc34/scratch/tanathep/py312/lib/python3.12/site-packages/sglang/srt/model_executor/model_runner.py", line 499, in model_specific_adjustment
[1,1]<stdout>:    self.init_double_sparsity_channel_config(server_args.ds_heavy_channel_type)
[1,1]<stdout>:  File "/home/users/industry/ai-hpc/apacsc34/scratch/tanathep/py312/lib/python3.12/site-packages/sglang/srt/model_executor/model_runner.py", line 1581, in init_double_sparsity_channel_config
[1,1]<stdout>:    with open(self.server_args.ds_channel_config_path, "r") as f:
[1,1]<stdout>:         ^^^^^^^^^^^^^^^^^^^^^^^^^^^^^^^^^^^^^^^^^^^^^^^^^^
[1,1]<stdout>:TypeError: expected str, bytes or os.PathLike object, not NoneType
[1,1]<stdout>:
[1,1]<stdout>:Process Process-1:4:
[1,1]<stdout>:Traceback (most recent call last):
[1,1]<stdout>:  File "/home/users/industry/ai-hpc/apacsc34/scratch/tanathep/py312/lib/python3.12/site-packages/sglang/srt/managers/scheduler.py", line 2555, in run_scheduler_process
[1,1]<stdout>:    scheduler = Scheduler(
[1,1]<stdout>:                ^^^^^^^^^^
[1,1]<stdout>:  File "/home/users/industry/ai-hpc/apacsc34/scratch/tanathep/py312/lib/python3.12/site-packages/sglang/srt/managers/scheduler.py", line 315, in __init__
[1,1]<stdout>:    self.tp_worker = TpWorkerClass(
[1,1]<stdout>:                     ^^^^^^^^^^^^^^
[1,1]<stdout>:  File "/home/users/industry/ai-hpc/apacsc34/scratch/tanathep/py312/lib/python3.12/site-packages/sglang/srt/managers/tp_worker.py", line 84, in __init__
[1,1]<stdout>:    self.model_runner = ModelRunner(
[1,1]<stdout>:                        ^^^^^^^^^^^^
[1,1]<stdout>:  File "/home/users/industry/ai-hpc/apacsc34/scratch/tanathep/py312/lib/python3.12/site-packages/sglang/srt/model_executor/model_runner.py", line 213, in __init__
[1,1]<stdout>:    self.model_specific_adjustment()
[1,1]<stdout>:  File "/home/users/industry/ai-hpc/apacsc34/scratch/tanathep/py312/lib/python3.12/site-packages/sglang/srt/model_executor/model_runner.py", line 499, in model_specific_adjustment
[1,1]<stdout>:    self.init_double_sparsity_channel_config(server_args.ds_heavy_channel_type)
[1,1]<stdout>:  File "/home/users/industry/ai-hpc/apacsc34/scratch/tanathep/py312/lib/python3.12/site-packages/sglang/srt/model_executor/model_runner.py", line 1581, in init_double_sparsity_channel_config
[1,1]<stdout>:    with open(self.server_args.ds_channel_config_path, "r") as f:
[1,1]<stdout>:         ^^^^^^^^^^^^^^^^^^^^^^^^^^^^^^^^^^^^^^^^^^^^^^^^^^
[1,1]<stdout>:TypeError: expected str, bytes or os.PathLike object, not NoneType
[1,1]<stdout>:
[1,1]<stdout>:During handling of the above exception, another exception occurred:
[1,1]<stdout>:
[1,1]<stdout>:Traceback (most recent call last):
[1,1]<stdout>:  File "/home/users/industry/ai-hpc/apacsc34/scratch/tanathep/py312/lib/python3.12/site-packages/psutil/__init__.py", line 1259, in _send_signal
[1,1]<stdout>:    os.kill(pid, sig)
[1,1]<stdout>:PermissionError: [Errno 1] Operation not permitted
[1,1]<stdout>:
[1,1]<stdout>:The above exception was the direct cause of the following exception:
[1,1]<stdout>:
[1,1]<stdout>:Traceback (most recent call last):
[1,1]<stdout>:  File "/home/users/industry/ai-hpc/apacsc34/scratch/tanathep/py312/lib/python3.12/multiprocessing/process.py", line 314, in _bootstrap
[1,1]<stdout>:    self.run()
[1,1]<stdout>:  File "/home/users/industry/ai-hpc/apacsc34/scratch/tanathep/py312/lib/python3.12/multiprocessing/process.py", line 108, in run
[1,1]<stdout>:    self._target(*self._args, **self._kwargs)
[1,1]<stdout>:  File "/home/users/industry/ai-hpc/apacsc34/scratch/tanathep/py312/lib/python3.12/site-packages/sglang/srt/managers/scheduler.py", line 2596, in run_scheduler_process
[1,1]<stdout>:    parent_process.send_signal(signal.SIGQUIT)
[1,1]<stdout>:  File "/home/users/industry/ai-hpc/apacsc34/scratch/tanathep/py312/lib/python3.12/site-packages/psutil/__init__.py", line 1277, in send_signal
[1,1]<stdout>:    self._send_signal(sig)
[1,1]<stdout>:  File "/home/users/industry/ai-hpc/apacsc34/scratch/tanathep/py312/lib/python3.12/site-packages/psutil/__init__.py", line 1268, in _send_signal
[1,1]<stdout>:    raise AccessDenied(pid, name) from err
[1,1]<stdout>:psutil.AccessDenied: (pid=1)
[1,0]<stdout>:[2025-10-12 02:27:59 DP0 TP7] Scheduler hit an exception: Traceback (most recent call last):
[1,0]<stdout>:  File "/home/users/industry/ai-hpc/apacsc34/scratch/tanathep/py312/lib/python3.12/site-packages/sglang/srt/managers/scheduler.py", line 2555, in run_scheduler_process
[1,0]<stdout>:    scheduler = Scheduler(
[1,0]<stdout>:                ^^^^^^^^^^
[1,0]<stdout>:  File "/home/users/industry/ai-hpc/apacsc34/scratch/tanathep/py312/lib/python3.12/site-packages/sglang/srt/managers/scheduler.py", line 315, in __init__
[1,0]<stdout>:    self.tp_worker = TpWorkerClass(
[1,0]<stdout>:                     ^^^^^^^^^^^^^^
[1,0]<stdout>:  File "/home/users/industry/ai-hpc/apacsc34/scratch/tanathep/py312/lib/python3.12/site-packages/sglang/srt/managers/tp_worker.py", line 84, in __init__
[1,0]<stdout>:    self.model_runner = ModelRunner(
[1,0]<stdout>:                        ^^^^^^^^^^^^
[1,0]<stdout>:  File "/home/users/industry/ai-hpc/apacsc34/scratch/tanathep/py312/lib/python3.12/site-packages/sglang/srt/model_executor/model_runner.py", line 213, in __init__
[1,0]<stdout>:    self.model_specific_adjustment()
[1,0]<stdout>:  File "/home/users/industry/ai-hpc/apacsc34/scratch/tanathep/py312/lib/python3.12/site-packages/sglang/srt/model_executor/model_runner.py", line 499, in model_specific_adjustment
[1,0]<stdout>:    self.init_double_sparsity_channel_config(server_args.ds_heavy_channel_type)
[1,0]<stdout>:  File "/home/users/industry/ai-hpc/apacsc34/scratch/tanathep/py312/lib/python3.12/site-packages/sglang/srt/model_executor/model_runner.py", line 1581, in init_double_sparsity_channel_config
[1,0]<stdout>:    with open(self.server_args.ds_channel_config_path, "r") as f:
[1,0]<stdout>:         ^^^^^^^^^^^^^^^^^^^^^^^^^^^^^^^^^^^^^^^^^^^^^^^^^^
[1,0]<stdout>:TypeError: expected str, bytes or os.PathLike object, not NoneType
[1,0]<stdout>:
[1,0]<stdout>:Process Process-1:9:
[1,0]<stdout>:Traceback (most recent call last):
[1,0]<stdout>:  File "/home/users/industry/ai-hpc/apacsc34/scratch/tanathep/py312/lib/python3.12/site-packages/sglang/srt/managers/scheduler.py", line 2555, in run_scheduler_process
[1,0]<stdout>:    scheduler = Scheduler(
[1,0]<stdout>:                ^^^^^^^^^^
[1,0]<stdout>:  File "/home/users/industry/ai-hpc/apacsc34/scratch/tanathep/py312/lib/python3.12/site-packages/sglang/srt/managers/scheduler.py", line 315, in __init__
[1,0]<stdout>:    self.tp_worker = TpWorkerClass(
[1,0]<stdout>:                     ^^^^^^^^^^^^^^
[1,0]<stdout>:  File "/home/users/industry/ai-hpc/apacsc34/scratch/tanathep/py312/lib/python3.12/site-packages/sglang/srt/managers/tp_worker.py", line 84, in __init__
[1,0]<stdout>:    self.model_runner = ModelRunner(
[1,0]<stdout>:                        ^^^^^^^^^^^^
[1,0]<stdout>:  File "/home/users/industry/ai-hpc/apacsc34/scratch/tanathep/py312/lib/python3.12/site-packages/sglang/srt/model_executor/model_runner.py", line 213, in __init__
[1,0]<stdout>:    self.model_specific_adjustment()
[1,0]<stdout>:  File "/home/users/industry/ai-hpc/apacsc34/scratch/tanathep/py312/lib/python3.12/site-packages/sglang/srt/model_executor/model_runner.py", line 499, in model_specific_adjustment
[1,0]<stdout>:    self.init_double_sparsity_channel_config(server_args.ds_heavy_channel_type)
[1,0]<stdout>:  File "/home/users/industry/ai-hpc/apacsc34/scratch/tanathep/py312/lib/python3.12/site-packages/sglang/srt/model_executor/model_runner.py", line 1581, in init_double_sparsity_channel_config
[1,0]<stdout>:    with open(self.server_args.ds_channel_config_path, "r") as f:
[1,0]<stdout>:         ^^^^^^^^^^^^^^^^^^^^^^^^^^^^^^^^^^^^^^^^^^^^^^^^^^
[1,0]<stdout>:TypeError: expected str, bytes or os.PathLike object, not NoneType
[1,0]<stdout>:
[1,0]<stdout>:During handling of the above exception, another exception occurred:
[1,0]<stdout>:
[1,0]<stdout>:Traceback (most recent call last):
[1,0]<stdout>:  File "/home/users/industry/ai-hpc/apacsc34/scratch/tanathep/py312/lib/python3.12/site-packages/psutil/__init__.py", line 1259, in _send_signal
[1,0]<stdout>:    os.kill(pid, sig)
[1,0]<stdout>:PermissionError: [Errno 1] Operation not permitted
[1,0]<stdout>:
[1,0]<stdout>:The above exception was the direct cause of the following exception:
[1,0]<stdout>:
[1,0]<stdout>:Traceback (most recent call last):
[1,0]<stdout>:  File "/home/users/industry/ai-hpc/apacsc34/scratch/tanathep/py312/lib/python3.12/multiprocessing/process.py", line 314, in _bootstrap
[1,0]<stdout>:    self.run()
[1,0]<stdout>:  File "/home/users/industry/ai-hpc/apacsc34/scratch/tanathep/py312/lib/python3.12/multiprocessing/process.py", line 108, in run
[1,0]<stdout>:    self._target(*self._args, **self._kwargs)
[1,0]<stdout>:  File "/home/users/industry/ai-hpc/apacsc34/scratch/tanathep/py312/lib/python3.12/site-packages/sglang/srt/managers/scheduler.py", line 2596, in run_scheduler_process
[1,0]<stdout>:    parent_process.send_signal(signal.SIGQUIT)
[1,0]<stdout>:  File "/home/users/industry/ai-hpc/apacsc34/scratch/tanathep/py312/lib/python3.12/site-packages/psutil/__init__.py", line 1277, in send_signal
[1,0]<stdout>:    self._send_signal(sig)
[1,0]<stdout>:  File "/home/users/industry/ai-hpc/apacsc34/scratch/tanathep/py312/lib/python3.12/site-packages/psutil/__init__.py", line 1268, in _send_signal
[1,0]<stdout>:    raise AccessDenied(pid, name) from err
[1,0]<stdout>:psutil.AccessDenied: (pid=1)
[1,1]<stdout>:[2025-10-12 02:27:59 DP1 TP13] Scheduler hit an exception: Traceback (most recent call last):
[1,1]<stdout>:  File "/home/users/industry/ai-hpc/apacsc34/scratch/tanathep/py312/lib/python3.12/site-packages/sglang/srt/managers/scheduler.py", line 2555, in run_scheduler_process
[1,1]<stdout>:    scheduler = Scheduler(
[1,1]<stdout>:                ^^^^^^^^^^
[1,1]<stdout>:  File "/home/users/industry/ai-hpc/apacsc34/scratch/tanathep/py312/lib/python3.12/site-packages/sglang/srt/managers/scheduler.py", line 315, in __init__
[1,1]<stdout>:    self.tp_worker = TpWorkerClass(
[1,1]<stdout>:                     ^^^^^^^^^^^^^^
[1,1]<stdout>:  File "/home/users/industry/ai-hpc/apacsc34/scratch/tanathep/py312/lib/python3.12/site-packages/sglang/srt/managers/tp_worker.py", line 84, in __init__
[1,1]<stdout>:    self.model_runner = ModelRunner(
[1,1]<stdout>:                        ^^^^^^^^^^^^
[1,1]<stdout>:  File "/home/users/industry/ai-hpc/apacsc34/scratch/tanathep/py312/lib/python3.12/site-packages/sglang/srt/model_executor/model_runner.py", line 213, in __init__
[1,1]<stdout>:    self.model_specific_adjustment()
[1,1]<stdout>:  File "/home/users/industry/ai-hpc/apacsc34/scratch/tanathep/py312/lib/python3.12/site-packages/sglang/srt/model_executor/model_runner.py", line 499, in model_specific_adjustment
[1,1]<stdout>:    self.init_double_sparsity_channel_config(server_args.ds_heavy_channel_type)
[1,1]<stdout>:  File "/home/users/industry/ai-hpc/apacsc34/scratch/tanathep/py312/lib/python3.12/site-packages/sglang/srt/model_executor/model_runner.py", line 1581, in init_double_sparsity_channel_config
[1,1]<stdout>:    with open(self.server_args.ds_channel_config_path, "r") as f:
[1,1]<stdout>:         ^^^^^^^^^^^^^^^^^^^^^^^^^^^^^^^^^^^^^^^^^^^^^^^^^^
[1,1]<stdout>:TypeError: expected str, bytes or os.PathLike object, not NoneType
[1,1]<stdout>:
[1,1]<stdout>:Process Process-1:7:
[1,1]<stdout>:Traceback (most recent call last):
[1,1]<stdout>:  File "/home/users/industry/ai-hpc/apacsc34/scratch/tanathep/py312/lib/python3.12/site-packages/sglang/srt/managers/scheduler.py", line 2555, in run_scheduler_process
[1,1]<stdout>:    scheduler = Scheduler(
[1,1]<stdout>:                ^^^^^^^^^^
[1,1]<stdout>:  File "/home/users/industry/ai-hpc/apacsc34/scratch/tanathep/py312/lib/python3.12/site-packages/sglang/srt/managers/scheduler.py", line 315, in __init__
[1,1]<stdout>:    self.tp_worker = TpWorkerClass(
[1,1]<stdout>:                     ^^^^^^^^^^^^^^
[1,1]<stdout>:  File "/home/users/industry/ai-hpc/apacsc34/scratch/tanathep/py312/lib/python3.12/site-packages/sglang/srt/managers/tp_worker.py", line 84, in __init__
[1,1]<stdout>:    self.model_runner = ModelRunner(
[1,1]<stdout>:                        ^^^^^^^^^^^^
[1,1]<stdout>:  File "/home/users/industry/ai-hpc/apacsc34/scratch/tanathep/py312/lib/python3.12/site-packages/sglang/srt/model_executor/model_runner.py", line 213, in __init__
[1,1]<stdout>:    self.model_specific_adjustment()
[1,1]<stdout>:  File "/home/users/industry/ai-hpc/apacsc34/scratch/tanathep/py312/lib/python3.12/site-packages/sglang/srt/model_executor/model_runner.py", line 499, in model_specific_adjustment
[1,1]<stdout>:    self.init_double_sparsity_channel_config(server_args.ds_heavy_channel_type)
[1,1]<stdout>:  File "/home/users/industry/ai-hpc/apacsc34/scratch/tanathep/py312/lib/python3.12/site-packages/sglang/srt/model_executor/model_runner.py", line 1581, in init_double_sparsity_channel_config
[1,1]<stdout>:    with open(self.server_args.ds_channel_config_path, "r") as f:
[1,1]<stdout>:         ^^^^^^^^^^^^^^^^^^^^^^^^^^^^^^^^^^^^^^^^^^^^^^^^^^
[1,1]<stdout>:TypeError: expected str, bytes or os.PathLike object, not NoneType
[1,1]<stdout>:
[1,1]<stdout>:During handling of the above exception, another exception occurred:
[1,1]<stdout>:
[1,1]<stdout>:Traceback (most recent call last):
[1,1]<stdout>:  File "/home/users/industry/ai-hpc/apacsc34/scratch/tanathep/py312/lib/python3.12/site-packages/psutil/__init__.py", line 1259, in _send_signal
[1,1]<stdout>:    os.kill(pid, sig)
[1,1]<stdout>:PermissionError: [Errno 1] Operation not permitted
[1,1]<stdout>:
[1,1]<stdout>:The above exception was the direct cause of the following exception:
[1,1]<stdout>:
[1,1]<stdout>:Traceback (most recent call last):
[1,1]<stdout>:  File "/home/users/industry/ai-hpc/apacsc34/scratch/tanathep/py312/lib/python3.12/multiprocessing/process.py", line 314, in _bootstrap
[1,1]<stdout>:    self.run()
[1,1]<stdout>:  File "/home/users/industry/ai-hpc/apacsc34/scratch/tanathep/py312/lib/python3.12/multiprocessing/process.py", line 108, in run
[1,1]<stdout>:    self._target(*self._args, **self._kwargs)
[1,1]<stdout>:  File "/home/users/industry/ai-hpc/apacsc34/scratch/tanathep/py312/lib/python3.12/site-packages/sglang/srt/managers/scheduler.py", line 2596, in run_scheduler_process
[1,1]<stdout>:    parent_process.send_signal(signal.SIGQUIT)
[1,1]<stdout>:  File "/home/users/industry/ai-hpc/apacsc34/scratch/tanathep/py312/lib/python3.12/site-packages/psutil/__init__.py", line 1277, in send_signal
[1,1]<stdout>:    self._send_signal(sig)
[1,1]<stdout>:  File "/home/users/industry/ai-hpc/apacsc34/scratch/tanathep/py312/lib/python3.12/site-packages/psutil/__init__.py", line 1268, in _send_signal
[1,1]<stdout>:    raise AccessDenied(pid, name) from err
[1,1]<stdout>:psutil.AccessDenied: (pid=1)
[1,1]<stdout>:[2025-10-12 02:27:59 DP1 TP11] Scheduler hit an exception: Traceback (most recent call last):
[1,1]<stdout>:  File "/home/users/industry/ai-hpc/apacsc34/scratch/tanathep/py312/lib/python3.12/site-packages/sglang/srt/managers/scheduler.py", line 2555, in run_scheduler_process
[1,1]<stdout>:    scheduler = Scheduler(
[1,1]<stdout>:                ^^^^^^^^^^
[1,1]<stdout>:  File "/home/users/industry/ai-hpc/apacsc34/scratch/tanathep/py312/lib/python3.12/site-packages/sglang/srt/managers/scheduler.py", line 315, in __init__
[1,1]<stdout>:    self.tp_worker = TpWorkerClass(
[1,1]<stdout>:                     ^^^^^^^^^^^^^^
[1,1]<stdout>:  File "/home/users/industry/ai-hpc/apacsc34/scratch/tanathep/py312/lib/python3.12/site-packages/sglang/srt/managers/tp_worker.py", line 84, in __init__
[1,1]<stdout>:    self.model_runner = ModelRunner(
[1,1]<stdout>:                        ^^^^^^^^^^^^
[1,1]<stdout>:  File "/home/users/industry/ai-hpc/apacsc34/scratch/tanathep/py312/lib/python3.12/site-packages/sglang/srt/model_executor/model_runner.py", line 213, in __init__
[1,1]<stdout>:    self.model_specific_adjustment()
[1,1]<stdout>:  File "/home/users/industry/ai-hpc/apacsc34/scratch/tanathep/py312/lib/python3.12/site-packages/sglang/srt/model_executor/model_runner.py", line 499, in model_specific_adjustment
[1,1]<stdout>:    self.init_double_sparsity_channel_config(server_args.ds_heavy_channel_type)
[1,1]<stdout>:  File "/home/users/industry/ai-hpc/apacsc34/scratch/tanathep/py312/lib/python3.12/site-packages/sglang/srt/model_executor/model_runner.py", line 1581, in init_double_sparsity_channel_config
[1,1]<stdout>:    with open(self.server_args.ds_channel_config_path, "r") as f:
[1,1]<stdout>:         ^^^^^^^^^^^^^^^^^^^^^^^^^^^^^^^^^^^^^^^^^^^^^^^^^^
[1,1]<stdout>:TypeError: expected str, bytes or os.PathLike object, not NoneType
[1,1]<stdout>:
[1,1]<stdout>:Process Process-1:5:
[1,1]<stdout>:Traceback (most recent call last):
[1,1]<stdout>:  File "/home/users/industry/ai-hpc/apacsc34/scratch/tanathep/py312/lib/python3.12/site-packages/sglang/srt/managers/scheduler.py", line 2555, in run_scheduler_process
[1,1]<stdout>:    scheduler = Scheduler(
[1,1]<stdout>:                ^^^^^^^^^^
[1,1]<stdout>:  File "/home/users/industry/ai-hpc/apacsc34/scratch/tanathep/py312/lib/python3.12/site-packages/sglang/srt/managers/scheduler.py", line 315, in __init__
[1,1]<stdout>:    self.tp_worker = TpWorkerClass(
[1,1]<stdout>:                     ^^^^^^^^^^^^^^
[1,1]<stdout>:  File "/home/users/industry/ai-hpc/apacsc34/scratch/tanathep/py312/lib/python3.12/site-packages/sglang/srt/managers/tp_worker.py", line 84, in __init__
[1,1]<stdout>:    self.model_runner = ModelRunner(
[1,1]<stdout>:                        ^^^^^^^^^^^^
[1,1]<stdout>:  File "/home/users/industry/ai-hpc/apacsc34/scratch/tanathep/py312/lib/python3.12/site-packages/sglang/srt/model_executor/model_runner.py", line 213, in __init__
[1,1]<stdout>:    self.model_specific_adjustment()
[1,1]<stdout>:  File "/home/users/industry/ai-hpc/apacsc34/scratch/tanathep/py312/lib/python3.12/site-packages/sglang/srt/model_executor/model_runner.py", line 499, in model_specific_adjustment
[1,1]<stdout>:    self.init_double_sparsity_channel_config(server_args.ds_heavy_channel_type)
[1,1]<stdout>:  File "/home/users/industry/ai-hpc/apacsc34/scratch/tanathep/py312/lib/python3.12/site-packages/sglang/srt/model_executor/model_runner.py", line 1581, in init_double_sparsity_channel_config
[1,1]<stdout>:    with open(self.server_args.ds_channel_config_path, "r") as f:
[1,1]<stdout>:         ^^^^^^^^^^^^^^^^^^^^^^^^^^^^^^^^^^^^^^^^^^^^^^^^^^
[1,1]<stdout>:TypeError: expected str, bytes or os.PathLike object, not NoneType
[1,1]<stdout>:
[1,1]<stdout>:During handling of the above exception, another exception occurred:
[1,1]<stdout>:
[1,1]<stdout>:Traceback (most recent call last):
[1,1]<stdout>:  File "/home/users/industry/ai-hpc/apacsc34/scratch/tanathep/py312/lib/python3.12/site-packages/psutil/__init__.py", line 1259, in _send_signal
[1,1]<stdout>:    os.kill(pid, sig)
[1,1]<stdout>:PermissionError: [Errno 1] Operation not permitted
[1,1]<stdout>:
[1,1]<stdout>:The above exception was the direct cause of the following exception:
[1,1]<stdout>:
[1,1]<stdout>:Traceback (most recent call last):
[1,1]<stdout>:  File "/home/users/industry/ai-hpc/apacsc34/scratch/tanathep/py312/lib/python3.12/multiprocessing/process.py", line 314, in _bootstrap
[1,1]<stdout>:    self.run()
[1,1]<stdout>:  File "/home/users/industry/ai-hpc/apacsc34/scratch/tanathep/py312/lib/python3.12/multiprocessing/process.py", line 108, in run
[1,1]<stdout>:    self._target(*self._args, **self._kwargs)
[1,1]<stdout>:  File "/home/users/industry/ai-hpc/apacsc34/scratch/tanathep/py312/lib/python3.12/site-packages/sglang/srt/managers/scheduler.py", line 2596, in run_scheduler_process
[1,1]<stdout>:    parent_process.send_signal(signal.SIGQUIT)
[1,1]<stdout>:  File "/home/users/industry/ai-hpc/apacsc34/scratch/tanathep/py312/lib/python3.12/site-packages/psutil/__init__.py", line 1277, in send_signal
[1,1]<stdout>:    self._send_signal(sig)
[1,1]<stdout>:  File "/home/users/industry/ai-hpc/apacsc34/scratch/tanathep/py312/lib/python3.12/site-packages/psutil/__init__.py", line 1268, in _send_signal
[1,1]<stdout>:    raise AccessDenied(pid, name) from err
[1,1]<stdout>:psutil.AccessDenied: (pid=1)
[1,0]<stdout>:[2025-10-12 02:27:59 DP0 TP3] Scheduler hit an exception: Traceback (most recent call last):
[1,0]<stdout>:  File "/home/users/industry/ai-hpc/apacsc34/scratch/tanathep/py312/lib/python3.12/site-packages/sglang/srt/managers/scheduler.py", line 2555, in run_scheduler_process
[1,0]<stdout>:    scheduler = Scheduler(
[1,0]<stdout>:                ^^^^^^^^^^
[1,0]<stdout>:  File "/home/users/industry/ai-hpc/apacsc34/scratch/tanathep/py312/lib/python3.12/site-packages/sglang/srt/managers/scheduler.py", line 315, in __init__
[1,0]<stdout>:    self.tp_worker = TpWorkerClass(
[1,0]<stdout>:                     ^^^^^^^^^^^^^^
[1,0]<stdout>:  File "/home/users/industry/ai-hpc/apacsc34/scratch/tanathep/py312/lib/python3.12/site-packages/sglang/srt/managers/tp_worker.py", line 84, in __init__
[1,0]<stdout>:    self.model_runner = ModelRunner(
[1,0]<stdout>:                        ^^^^^^^^^^^^
[1,0]<stdout>:  File "/home/users/industry/ai-hpc/apacsc34/scratch/tanathep/py312/lib/python3.12/site-packages/sglang/srt/model_executor/model_runner.py", line 213, in __init__
[1,0]<stdout>:    self.model_specific_adjustment()
[1,0]<stdout>:  File "/home/users/industry/ai-hpc/apacsc34/scratch/tanathep/py312/lib/python3.12/site-packages/sglang/srt/model_executor/model_runner.py", line 499, in model_specific_adjustment
[1,0]<stdout>:    self.init_double_sparsity_channel_config(server_args.ds_heavy_channel_type)
[1,0]<stdout>:  File "/home/users/industry/ai-hpc/apacsc34/scratch/tanathep/py312/lib/python3.12/site-packages/sglang/srt/model_executor/model_runner.py", line 1581, in init_double_sparsity_channel_config
[1,0]<stdout>:    with open(self.server_args.ds_channel_config_path, "r") as f:
[1,0]<stdout>:         ^^^^^^^^^^^^^^^^^^^^^^^^^^^^^^^^^^^^^^^^^^^^^^^^^^
[1,0]<stdout>:TypeError: expected str, bytes or os.PathLike object, not NoneType
[1,0]<stdout>:
[1,0]<stdout>:Process Process-1:5:
[1,0]<stdout>:Traceback (most recent call last):
[1,0]<stdout>:  File "/home/users/industry/ai-hpc/apacsc34/scratch/tanathep/py312/lib/python3.12/site-packages/sglang/srt/managers/scheduler.py", line 2555, in run_scheduler_process
[1,0]<stdout>:    scheduler = Scheduler(
[1,0]<stdout>:                ^^^^^^^^^^
[1,0]<stdout>:  File "/home/users/industry/ai-hpc/apacsc34/scratch/tanathep/py312/lib/python3.12/site-packages/sglang/srt/managers/scheduler.py", line 315, in __init__
[1,0]<stdout>:    self.tp_worker = TpWorkerClass(
[1,0]<stdout>:                     ^^^^^^^^^^^^^^
[1,0]<stdout>:  File "/home/users/industry/ai-hpc/apacsc34/scratch/tanathep/py312/lib/python3.12/site-packages/sglang/srt/managers/tp_worker.py", line 84, in __init__
[1,0]<stdout>:    self.model_runner = ModelRunner(
[1,0]<stdout>:                        ^^^^^^^^^^^^
[1,0]<stdout>:  File "/home/users/industry/ai-hpc/apacsc34/scratch/tanathep/py312/lib/python3.12/site-packages/sglang/srt/model_executor/model_runner.py", line 213, in __init__
[1,0]<stdout>:    self.model_specific_adjustment()
[1,0]<stdout>:  File "/home/users/industry/ai-hpc/apacsc34/scratch/tanathep/py312/lib/python3.12/site-packages/sglang/srt/model_executor/model_runner.py", line 499, in model_specific_adjustment
[1,0]<stdout>:    self.init_double_sparsity_channel_config(server_args.ds_heavy_channel_type)
[1,0]<stdout>:  File "/home/users/industry/ai-hpc/apacsc34/scratch/tanathep/py312/lib/python3.12/site-packages/sglang/srt/model_executor/model_runner.py", line 1581, in init_double_sparsity_channel_config
[1,0]<stdout>:    with open(self.server_args.ds_channel_config_path, "r") as f:
[1,0]<stdout>:         ^^^^^^^^^^^^^^^^^^^^^^^^^^^^^^^^^^^^^^^^^^^^^^^^^^
[1,0]<stdout>:TypeError: expected str, bytes or os.PathLike object, not NoneType
[1,0]<stdout>:
[1,0]<stdout>:During handling of the above exception, another exception occurred:
[1,0]<stdout>:
[1,0]<stdout>:Traceback (most recent call last):
[1,0]<stdout>:  File "/home/users/industry/ai-hpc/apacsc34/scratch/tanathep/py312/lib/python3.12/site-packages/psutil/__init__.py", line 1259, in _send_signal
[1,0]<stdout>:    os.kill(pid, sig)
[1,0]<stdout>:PermissionError: [Errno 1] Operation not permitted
[1,0]<stdout>:
[1,0]<stdout>:The above exception was the direct cause of the following exception:
[1,0]<stdout>:
[1,0]<stdout>:Traceback (most recent call last):
[1,0]<stdout>:  File "/home/users/industry/ai-hpc/apacsc34/scratch/tanathep/py312/lib/python3.12/multiprocessing/process.py", line 314, in _bootstrap
[1,0]<stdout>:    self.run()
[1,0]<stdout>:  File "/home/users/industry/ai-hpc/apacsc34/scratch/tanathep/py312/lib/python3.12/multiprocessing/process.py", line 108, in run
[1,0]<stdout>:    self._target(*self._args, **self._kwargs)
[1,0]<stdout>:  File "/home/users/industry/ai-hpc/apacsc34/scratch/tanathep/py312/lib/python3.12/site-packages/sglang/srt/managers/scheduler.py", line 2596, in run_scheduler_process
[1,0]<stdout>:    parent_process.send_signal(signal.SIGQUIT)
[1,0]<stdout>:  File "/home/users/industry/ai-hpc/apacsc34/scratch/tanathep/py312/lib/python3.12/site-packages/psutil/__init__.py", line 1277, in send_signal
[1,0]<stdout>:    self._send_signal(sig)
[1,0]<stdout>:  File "/home/users/industry/ai-hpc/apacsc34/scratch/tanathep/py312/lib/python3.12/site-packages/psutil/__init__.py", line 1268, in _send_signal
[1,0]<stdout>:    raise AccessDenied(pid, name) from err
[1,0]<stdout>:psutil.AccessDenied: (pid=1)
[1,0]<stdout>:[2025-10-12 02:27:59 DP0 TP5] Scheduler hit an exception: Traceback (most recent call last):
[1,0]<stdout>:  File "/home/users/industry/ai-hpc/apacsc34/scratch/tanathep/py312/lib/python3.12/site-packages/sglang/srt/managers/scheduler.py", line 2555, in run_scheduler_process
[1,0]<stdout>:    scheduler = Scheduler(
[1,0]<stdout>:                ^^^^^^^^^^
[1,0]<stdout>:  File "/home/users/industry/ai-hpc/apacsc34/scratch/tanathep/py312/lib/python3.12/site-packages/sglang/srt/managers/scheduler.py", line 315, in __init__
[1,0]<stdout>:    self.tp_worker = TpWorkerClass(
[1,0]<stdout>:                     ^^^^^^^^^^^^^^
[1,0]<stdout>:  File "/home/users/industry/ai-hpc/apacsc34/scratch/tanathep/py312/lib/python3.12/site-packages/sglang/srt/managers/tp_worker.py", line 84, in __init__
[1,0]<stdout>:    self.model_runner = ModelRunner(
[1,0]<stdout>:                        ^^^^^^^^^^^^
[1,0]<stdout>:  File "/home/users/industry/ai-hpc/apacsc34/scratch/tanathep/py312/lib/python3.12/site-packages/sglang/srt/model_executor/model_runner.py", line 213, in __init__
[1,0]<stdout>:    self.model_specific_adjustment()
[1,0]<stdout>:  File "/home/users/industry/ai-hpc/apacsc34/scratch/tanathep/py312/lib/python3.12/site-packages/sglang/srt/model_executor/model_runner.py", line 499, in model_specific_adjustment
[1,0]<stdout>:    self.init_double_sparsity_channel_config(server_args.ds_heavy_channel_type)
[1,0]<stdout>:  File "/home/users/industry/ai-hpc/apacsc34/scratch/tanathep/py312/lib/python3.12/site-packages/sglang/srt/model_executor/model_runner.py", line 1581, in init_double_sparsity_channel_config
[1,0]<stdout>:    with open(self.server_args.ds_channel_config_path, "r") as f:
[1,0]<stdout>:         ^^^^^^^^^^^^^^^^^^^^^^^^^^^^^^^^^^^^^^^^^^^^^^^^^^
[1,0]<stdout>:TypeError: expected str, bytes or os.PathLike object, not NoneType
[1,0]<stdout>:
[1,0]<stdout>:Process Process-1:7:
[1,0]<stdout>:Traceback (most recent call last):
[1,0]<stdout>:  File "/home/users/industry/ai-hpc/apacsc34/scratch/tanathep/py312/lib/python3.12/site-packages/sglang/srt/managers/scheduler.py", line 2555, in run_scheduler_process
[1,0]<stdout>:    scheduler = Scheduler(
[1,0]<stdout>:                ^^^^^^^^^^
[1,0]<stdout>:  File "/home/users/industry/ai-hpc/apacsc34/scratch/tanathep/py312/lib/python3.12/site-packages/sglang/srt/managers/scheduler.py", line 315, in __init__
[1,0]<stdout>:    self.tp_worker = TpWorkerClass(
[1,0]<stdout>:                     ^^^^^^^^^^^^^^
[1,0]<stdout>:  File "/home/users/industry/ai-hpc/apacsc34/scratch/tanathep/py312/lib/python3.12/site-packages/sglang/srt/managers/tp_worker.py", line 84, in __init__
[1,0]<stdout>:    self.model_runner = ModelRunner(
[1,0]<stdout>:                        ^^^^^^^^^^^^
[1,0]<stdout>:  File "/home/users/industry/ai-hpc/apacsc34/scratch/tanathep/py312/lib/python3.12/site-packages/sglang/srt/model_executor/model_runner.py", line 213, in __init__
[1,0]<stdout>:    self.model_specific_adjustment()
[1,0]<stdout>:  File "/home/users/industry/ai-hpc/apacsc34/scratch/tanathep/py312/lib/python3.12/site-packages/sglang/srt/model_executor/model_runner.py", line 499, in model_specific_adjustment
[1,0]<stdout>:    self.init_double_sparsity_channel_config(server_args.ds_heavy_channel_type)
[1,0]<stdout>:  File "/home/users/industry/ai-hpc/apacsc34/scratch/tanathep/py312/lib/python3.12/site-packages/sglang/srt/model_executor/model_runner.py", line 1581, in init_double_sparsity_channel_config
[1,0]<stdout>:    with open(self.server_args.ds_channel_config_path, "r") as f:
[1,0]<stdout>:         ^^^^^^^^^^^^^^^^^^^^^^^^^^^^^^^^^^^^^^^^^^^^^^^^^^
[1,0]<stdout>:TypeError: expected str, bytes or os.PathLike object, not NoneType
[1,0]<stdout>:
[1,0]<stdout>:During handling of the above exception, another exception occurred:
[1,0]<stdout>:
[1,0]<stdout>:Traceback (most recent call last):
[1,0]<stdout>:  File "/home/users/industry/ai-hpc/apacsc34/scratch/tanathep/py312/lib/python3.12/site-packages/psutil/__init__.py", line 1259, in _send_signal
[1,0]<stdout>:    os.kill(pid, sig)
[1,0]<stdout>:PermissionError: [Errno 1] Operation not permitted
[1,0]<stdout>:
[1,0]<stdout>:The above exception was the direct cause of the following exception:
[1,0]<stdout>:
[1,0]<stdout>:Traceback (most recent call last):
[1,0]<stdout>:  File "/home/users/industry/ai-hpc/apacsc34/scratch/tanathep/py312/lib/python3.12/multiprocessing/process.py", line 314, in _bootstrap
[1,0]<stdout>:    self.run()
[1,0]<stdout>:  File "/home/users/industry/ai-hpc/apacsc34/scratch/tanathep/py312/lib/python3.12/multiprocessing/process.py", line 108, in run
[1,0]<stdout>:    self._target(*self._args, **self._kwargs)
[1,0]<stdout>:  File "/home/users/industry/ai-hpc/apacsc34/scratch/tanathep/py312/lib/python3.12/site-packages/sglang/srt/managers/scheduler.py", line 2596, in run_scheduler_process
[1,0]<stdout>:    parent_process.send_signal(signal.SIGQUIT)
[1,0]<stdout>:  File "/home/users/industry/ai-hpc/apacsc34/scratch/tanathep/py312/lib/python3.12/site-packages/psutil/__init__.py", line 1277, in send_signal
[1,0]<stdout>:    self._send_signal(sig)
[1,0]<stdout>:  File "/home/users/industry/ai-hpc/apacsc34/scratch/tanathep/py312/lib/python3.12/site-packages/psutil/__init__.py", line 1268, in _send_signal
[1,0]<stdout>:    raise AccessDenied(pid, name) from err
[1,0]<stdout>:psutil.AccessDenied: (pid=1)
[1,0]<stdout>:[2025-10-12 02:27:59 DP0 TP0] MLA optimization is turned on. Use fa3 backend.
[1,0]<stdout>:[2025-10-12 02:27:59 DP0 TP0] Double sparsity optimization is turned on. Use triton backend without CUDA graph.
[1,0]<stdout>:[2025-10-12 02:27:59 DP0 TP0] Scheduler hit an exception: Traceback (most recent call last):
[1,0]<stdout>:  File "/home/users/industry/ai-hpc/apacsc34/scratch/tanathep/py312/lib/python3.12/site-packages/sglang/srt/managers/scheduler.py", line 2555, in run_scheduler_process
[1,0]<stdout>:    scheduler = Scheduler(
[1,0]<stdout>:                ^^^^^^^^^^
[1,0]<stdout>:  File "/home/users/industry/ai-hpc/apacsc34/scratch/tanathep/py312/lib/python3.12/site-packages/sglang/srt/managers/scheduler.py", line 315, in __init__
[1,0]<stdout>:    self.tp_worker = TpWorkerClass(
[1,0]<stdout>:                     ^^^^^^^^^^^^^^
[1,0]<stdout>:  File "/home/users/industry/ai-hpc/apacsc34/scratch/tanathep/py312/lib/python3.12/site-packages/sglang/srt/managers/tp_worker.py", line 84, in __init__
[1,0]<stdout>:    self.model_runner = ModelRunner(
[1,0]<stdout>:                        ^^^^^^^^^^^^
[1,0]<stdout>:  File "/home/users/industry/ai-hpc/apacsc34/scratch/tanathep/py312/lib/python3.12/site-packages/sglang/srt/model_executor/model_runner.py", line 213, in __init__
[1,0]<stdout>:    self.model_specific_adjustment()
[1,0]<stdout>:  File "/home/users/industry/ai-hpc/apacsc34/scratch/tanathep/py312/lib/python3.12/site-packages/sglang/srt/model_executor/model_runner.py", line 499, in model_specific_adjustment
[1,0]<stdout>:    self.init_double_sparsity_channel_config(server_args.ds_heavy_channel_type)
[1,0]<stdout>:  File "/home/users/industry/ai-hpc/apacsc34/scratch/tanathep/py312/lib/python3.12/site-packages/sglang/srt/model_executor/model_runner.py", line 1581, in init_double_sparsity_channel_config
[1,0]<stdout>:    with open(self.server_args.ds_channel_config_path, "r") as f:
[1,0]<stdout>:         ^^^^^^^^^^^^^^^^^^^^^^^^^^^^^^^^^^^^^^^^^^^^^^^^^^
[1,0]<stdout>:TypeError: expected str, bytes or os.PathLike object, not NoneType
[1,0]<stdout>:
[1,0]<stdout>:Process Process-1:2:
[1,0]<stdout>:Traceback (most recent call last):
[1,0]<stdout>:  File "/home/users/industry/ai-hpc/apacsc34/scratch/tanathep/py312/lib/python3.12/site-packages/sglang/srt/managers/scheduler.py", line 2555, in run_scheduler_process
[1,0]<stdout>:    scheduler = Scheduler(
[1,0]<stdout>:                ^^^^^^^^^^
[1,0]<stdout>:  File "/home/users/industry/ai-hpc/apacsc34/scratch/tanathep/py312/lib/python3.12/site-packages/sglang/srt/managers/scheduler.py", line 315, in __init__
[1,0]<stdout>:    self.tp_worker = TpWorkerClass(
[1,0]<stdout>:                     ^^^^^^^^^^^^^^
[1,0]<stdout>:  File "/home/users/industry/ai-hpc/apacsc34/scratch/tanathep/py312/lib/python3.12/site-packages/sglang/srt/managers/tp_worker.py", line 84, in __init__
[1,0]<stdout>:    self.model_runner = ModelRunner(
[1,0]<stdout>:                        ^^^^^^^^^^^^
[1,0]<stdout>:  File "/home/users/industry/ai-hpc/apacsc34/scratch/tanathep/py312/lib/python3.12/site-packages/sglang/srt/model_executor/model_runner.py", line 213, in __init__
[1,0]<stdout>:    self.model_specific_adjustment()
[1,0]<stdout>:  File "/home/users/industry/ai-hpc/apacsc34/scratch/tanathep/py312/lib/python3.12/site-packages/sglang/srt/model_executor/model_runner.py", line 499, in model_specific_adjustment
[1,0]<stdout>:    self.init_double_sparsity_channel_config(server_args.ds_heavy_channel_type)
[1,0]<stdout>:  File "/home/users/industry/ai-hpc/apacsc34/scratch/tanathep/py312/lib/python3.12/site-packages/sglang/srt/model_executor/model_runner.py", line 1581, in init_double_sparsity_channel_config
[1,0]<stdout>:    with open(self.server_args.ds_channel_config_path, "r") as f:
[1,0]<stdout>:         ^^^^^^^^^^^^^^^^^^^^^^^^^^^^^^^^^^^^^^^^^^^^^^^^^^
[1,0]<stdout>:TypeError: expected str, bytes or os.PathLike object, not NoneType
[1,0]<stdout>:
[1,0]<stdout>:During handling of the above exception, another exception occurred:
[1,0]<stdout>:
[1,0]<stdout>:Traceback (most recent call last):
[1,0]<stdout>:  File "/home/users/industry/ai-hpc/apacsc34/scratch/tanathep/py312/lib/python3.12/site-packages/psutil/__init__.py", line 1259, in _send_signal
[1,0]<stdout>:    os.kill(pid, sig)
[1,0]<stdout>:PermissionError: [Errno 1] Operation not permitted
[1,0]<stdout>:
[1,0]<stdout>:The above exception was the direct cause of the following exception:
[1,0]<stdout>:
[1,0]<stdout>:Traceback (most recent call last):
[1,0]<stdout>:  File "/home/users/industry/ai-hpc/apacsc34/scratch/tanathep/py312/lib/python3.12/multiprocessing/process.py", line 314, in _bootstrap
[1,0]<stdout>:    self.run()
[1,0]<stdout>:  File "/home/users/industry/ai-hpc/apacsc34/scratch/tanathep/py312/lib/python3.12/multiprocessing/process.py", line 108, in run
[1,0]<stdout>:    self._target(*self._args, **self._kwargs)
[1,0]<stdout>:  File "/home/users/industry/ai-hpc/apacsc34/scratch/tanathep/py312/lib/python3.12/site-packages/sglang/srt/managers/scheduler.py", line 2596, in run_scheduler_process
[1,0]<stdout>:    parent_process.send_signal(signal.SIGQUIT)
[1,0]<stdout>:  File "/home/users/industry/ai-hpc/apacsc34/scratch/tanathep/py312/lib/python3.12/site-packages/psutil/__init__.py", line 1277, in send_signal
[1,0]<stdout>:    self._send_signal(sig)
[1,0]<stdout>:  File "/home/users/industry/ai-hpc/apacsc34/scratch/tanathep/py312/lib/python3.12/site-packages/psutil/__init__.py", line 1268, in _send_signal
[1,0]<stdout>:    raise AccessDenied(pid, name) from err
[1,0]<stdout>:psutil.AccessDenied: (pid=1)
[1,0]<stdout>:[2025-10-12 02:27:59 DP0 TP4] Scheduler hit an exception: Traceback (most recent call last):
[1,0]<stdout>:  File "/home/users/industry/ai-hpc/apacsc34/scratch/tanathep/py312/lib/python3.12/site-packages/sglang/srt/managers/scheduler.py", line 2555, in run_scheduler_process
[1,0]<stdout>:    scheduler = Scheduler(
[1,0]<stdout>:                ^^^^^^^^^^
[1,0]<stdout>:  File "/home/users/industry/ai-hpc/apacsc34/scratch/tanathep/py312/lib/python3.12/site-packages/sglang/srt/managers/scheduler.py", line 315, in __init__
[1,0]<stdout>:    self.tp_worker = TpWorkerClass(
[1,0]<stdout>:                     ^^^^^^^^^^^^^^
[1,0]<stdout>:  File "/home/users/industry/ai-hpc/apacsc34/scratch/tanathep/py312/lib/python3.12/site-packages/sglang/srt/managers/tp_worker.py", line 84, in __init__
[1,0]<stdout>:    self.model_runner = ModelRunner(
[1,0]<stdout>:                        ^^^^^^^^^^^^
[1,0]<stdout>:  File "/home/users/industry/ai-hpc/apacsc34/scratch/tanathep/py312/lib/python3.12/site-packages/sglang/srt/model_executor/model_runner.py", line 213, in __init__
[1,0]<stdout>:    self.model_specific_adjustment()
[1,0]<stdout>:  File "/home/users/industry/ai-hpc/apacsc34/scratch/tanathep/py312/lib/python3.12/site-packages/sglang/srt/model_executor/model_runner.py", line 499, in model_specific_adjustment
[1,0]<stdout>:    self.init_double_sparsity_channel_config(server_args.ds_heavy_channel_type)
[1,0]<stdout>:  File "/home/users/industry/ai-hpc/apacsc34/scratch/tanathep/py312/lib/python3.12/site-packages/sglang/srt/model_executor/model_runner.py", line 1581, in init_double_sparsity_channel_config
[1,0]<stdout>:    with open(self.server_args.ds_channel_config_path, "r") as f:
[1,0]<stdout>:         ^^^^^^^^^^^^^^^^^^^^^^^^^^^^^^^^^^^^^^^^^^^^^^^^^^
[1,0]<stdout>:TypeError: expected str, bytes or os.PathLike object, not NoneType
[1,0]<stdout>:
[1,0]<stdout>:Process Process-1:6:
[1,0]<stdout>:Traceback (most recent call last):
[1,0]<stdout>:  File "/home/users/industry/ai-hpc/apacsc34/scratch/tanathep/py312/lib/python3.12/site-packages/sglang/srt/managers/scheduler.py", line 2555, in run_scheduler_process
[1,0]<stdout>:    scheduler = Scheduler(
[1,0]<stdout>:                ^^^^^^^^^^
[1,0]<stdout>:  File "/home/users/industry/ai-hpc/apacsc34/scratch/tanathep/py312/lib/python3.12/site-packages/sglang/srt/managers/scheduler.py", line 315, in __init__
[1,0]<stdout>:    self.tp_worker = TpWorkerClass(
[1,0]<stdout>:                     ^^^^^^^^^^^^^^
[1,0]<stdout>:  File "/home/users/industry/ai-hpc/apacsc34/scratch/tanathep/py312/lib/python3.12/site-packages/sglang/srt/managers/tp_worker.py", line 84, in __init__
[1,0]<stdout>:    self.model_runner = ModelRunner(
[1,0]<stdout>:                        ^^^^^^^^^^^^
[1,0]<stdout>:  File "/home/users/industry/ai-hpc/apacsc34/scratch/tanathep/py312/lib/python3.12/site-packages/sglang/srt/model_executor/model_runner.py", line 213, in __init__
[1,0]<stdout>:    self.model_specific_adjustment()
[1,0]<stdout>:  File "/home/users/industry/ai-hpc/apacsc34/scratch/tanathep/py312/lib/python3.12/site-packages/sglang/srt/model_executor/model_runner.py", line 499, in model_specific_adjustment
[1,0]<stdout>:    self.init_double_sparsity_channel_config(server_args.ds_heavy_channel_type)
[1,0]<stdout>:  File "/home/users/industry/ai-hpc/apacsc34/scratch/tanathep/py312/lib/python3.12/site-packages/sglang/srt/model_executor/model_runner.py", line 1581, in init_double_sparsity_channel_config
[1,0]<stdout>:    with open(self.server_args.ds_channel_config_path, "r") as f:
[1,0]<stdout>:         ^^^^^^^^^^^^^^^^^^^^^^^^^^^^^^^^^^^^^^^^^^^^^^^^^^
[1,0]<stdout>:TypeError: expected str, bytes or os.PathLike object, not NoneType
[1,0]<stdout>:
[1,0]<stdout>:During handling of the above exception, another exception occurred:
[1,0]<stdout>:
[1,0]<stdout>:Traceback (most recent call last):
[1,0]<stdout>:  File "/home/users/industry/ai-hpc/apacsc34/scratch/tanathep/py312/lib/python3.12/site-packages/psutil/__init__.py", line 1259, in _send_signal
[1,0]<stdout>:    os.kill(pid, sig)
[1,0]<stdout>:PermissionError: [Errno 1] Operation not permitted
[1,0]<stdout>:
[1,0]<stdout>:The above exception was the direct cause of the following exception:
[1,0]<stdout>:
[1,0]<stdout>:Traceback (most recent call last):
[1,0]<stdout>:  File "/home/users/industry/ai-hpc/apacsc34/scratch/tanathep/py312/lib/python3.12/multiprocessing/process.py", line 314, in _bootstrap
[1,0]<stdout>:    self.run()
[1,0]<stdout>:  File "/home/users/industry/ai-hpc/apacsc34/scratch/tanathep/py312/lib/python3.12/multiprocessing/process.py", line 108, in run
[1,0]<stdout>:    self._target(*self._args, **self._kwargs)
[1,0]<stdout>:  File "/home/users/industry/ai-hpc/apacsc34/scratch/tanathep/py312/lib/python3.12/site-packages/sglang/srt/managers/scheduler.py", line 2596, in run_scheduler_process
[1,0]<stdout>:    parent_process.send_signal(signal.SIGQUIT)
[1,0]<stdout>:  File "/home/users/industry/ai-hpc/apacsc34/scratch/tanathep/py312/lib/python3.12/site-packages/psutil/__init__.py", line 1277, in send_signal
[1,0]<stdout>:    self._send_signal(sig)
[1,0]<stdout>:  File "/home/users/industry/ai-hpc/apacsc34/scratch/tanathep/py312/lib/python3.12/site-packages/psutil/__init__.py", line 1268, in _send_signal
[1,0]<stdout>:    raise AccessDenied(pid, name) from err
[1,0]<stdout>:psutil.AccessDenied: (pid=1)
=>> PBS: job killed: walltime 603 exceeded limit 600
~~~~~~~~~~~~~~~~~~~~~~~~~~~~~~~~~~~~~~~~~~~~~~~~~~~~~~~~~~~~~~~~~~~~~~~~~~~~~~~~~~~~~~~~~~
			Resource Usage on 2025-10-12 02:37:11.912176:
~~~~~~~~~~~~~~~~~~~~~~~~~~~~~~~~~~~~~~~~~~~~~~~~~~~~~~~~~~~~~~~~~~~~~~~~~~~~~~~~~~~~~~~~~~
	JobId: 97117.pbs111
	Project: 50000128
	Exit Status: -29
~~~~~~~~~~~~~~~~~~~~~~~~~~~~~~~~~~~~~~~~~~~~~~~~~~~~~~~~~~~~~~~~~~~~~~~~~~~~~~~~~~~~~~~~~~
	NCPUs: Requested(224), Used(224)
	CPU Time Used: 00:08:34
	Memory: Requested(3760gb), Used(11575536kb)
	Vmem Used: 36265960848kb
	Walltime: Requested(00:10:00), Used(00:10:14)
~~~~~~~~~~~~~~~~~~~~~~~~~~~~~~~~~~~~~~~~~~~~~~~~~~~~~~~~~~~~~~~~~~~~~~~~~~~~~~~~~~~~~~~~~~
	Execution Nodes Used: (a2ap-dgx007:ncpus=112:ngpus=8:mem=1971322880kb)+(a2ap-dgx010:ncpus=112:ngpus=8:mem=1971322880kb)
~~~~~~~~~~~~~~~~~~~~~~~~~~~~~~~~~~~~~~~~~~~~~~~~~~~~~~~~~~~~~~~~~~~~~~~~~~~~~~~~~~~~~~~~~~
	GPU Duration: 10.42mins
	GPU Power Consumed: 142.39W
	GPU Max GPU Memory Used: 0.0B
	Memory Throughput Rate (Average): a2ap-dgx007:(gpu1:0%+gpu0:0%+gpu2:0%+gpu3:0%+gpu5:0%+gpu4:0%+gpu6:0%+gpu7:0%)+a2ap-dgx010:(gpu1:0%+gpu0:0%+gpu2:0%+gpu3:0%+gpu5:0%+gpu4:0%+gpu6:0%+gpu7:0%)
	Memory Throughput Rate (Max): a2ap-dgx007:(gpu1:0%+gpu0:0%+gpu2:0%+gpu3:0%+gpu5:0%+gpu4:0%+gpu6:0%+gpu7:0%)+a2ap-dgx010:(gpu1:0%+gpu0:0%+gpu2:0%+gpu3:0%+gpu5:0%+gpu4:0%+gpu6:0%+gpu7:0%)
	Memory Throughput Rate (Min): a2ap-dgx007:(gpu1:0%+gpu0:0%+gpu2:0%+gpu3:0%+gpu5:0%+gpu4:0%+gpu6:0%+gpu7:0%)+a2ap-dgx010:(gpu1:0%+gpu0:0%+gpu2:0%+gpu3:0%+gpu5:0%+gpu4:0%+gpu6:0%+gpu7:0%)
	GPU SM Utilization (Average): a2ap-dgx007:(gpu1:0%+gpu0:0%+gpu2:0%+gpu3:0%+gpu5:0%+gpu4:0%+gpu6:0%+gpu7:0%)+a2ap-dgx010:(gpu1:0%+gpu0:0%+gpu2:0%+gpu3:0%+gpu5:0%+gpu4:0%+gpu6:0%+gpu7:0%)
	GPU SM Utilization (Max): a2ap-dgx007:(gpu1:0%+gpu0:0%+gpu2:0%+gpu3:0%+gpu5:0%+gpu4:0%+gpu6:0%+gpu7:0%)+a2ap-dgx010:(gpu1:0%+gpu0:0%+gpu2:0%+gpu3:0%+gpu5:0%+gpu4:0%+gpu6:0%+gpu7:0%)
	GPU SM Utilization (Min): a2ap-dgx007:(gpu1:0%+gpu0:0%+gpu2:0%+gpu3:0%+gpu5:0%+gpu4:0%+gpu6:0%+gpu7:0%)+a2ap-dgx010:(gpu1:0%+gpu0:0%+gpu2:0%+gpu3:0%+gpu5:0%+gpu4:0%+gpu6:0%+gpu7:0%)
~~~~~~~~~~~~~~~~~~~~~~~~~~~~~~~~~~~~~~~~~~~~~~~~~~~~~~~~~~~~~~~~~~~~~~~~~~~~~~~~~~~~~~~~~~
Warning: All GPUs have a percentage of 0 utilisation.
GPU application profile: Idle
~~~~~~~~~~~~~~~~~~~~~~~~~~~~~~~~~~~~~~~~~~~~~~~~~~~~~~~~~~~~~~~~~~~~~~~~~~~~~~~~~~~~~~~~~~

